Workbook
Name Projects: #REF!
Name Projects: #REF!
Name Projects: #REF!
Name Projects: #REF!
Name Projects: #REF!
Name Projects: #REF!
Name Projects: #REF!
Name Projects: #REF!
Name Projects: #REF!
Name Projects: #REF!
Name Projects: #REF!
Name Projects: #REF!
Name Projects: #REF!
Name Projects: #REF!
Name ValidProjects: #REF!
Name ValidProjects: #REF!
Name ValidProjects: #REF!
Name ValidProjects: #REF!
Name ValidProjects: #REF!
Name ValidProjects: #REF!
Name ValidProjects: #REF!
Name ValidProjects: #REF!
Name ValidProjects: #REF!
Name ValidProjects: #REF!
Name ValidProjects: #REF!
Name ValidProjects: #REF!
Name ValidProjects: #REF!
Name ValidProjects: #REF!

Sheet JAN 
B2: MONTHLY TIME RECORD
B3: Name: | D3: ='Yearly Info'!A45 -> Don Woods
B4: Month: | D4: ='Yearly Info'!D1 -> 46023 | J4: Year: | L4: ='Yearly Info'!B1 -> 2026
A6: Project No. & Description | B6: Day of the Month | AI6: Total Hours
B7: =IF(WEEKDAY(D$4,2)>5,D$4+8 - WEEKDAY(D$4,2),D$4-(WEEKDAY(D$4,2)-1)) -> 46020 | C7: =B7+1 -> 46021 | D7: =C7+1 -> 46022 | E7: =D7+1 -> 46023 | F7: =E7+1 -> 46024 | G7: =F7+1 -> 46025 | H7: =G7+1 -> 46026 | I7: =H7+1 -> 46027 | J7: =I7+1 -> 46028 | ... AH7: =AG7+1 -> 46052 | AI7: Hours
B8: =HYPERLINK("#'"&UPPER(LEFT(TEXT($D$4,"mmmm"),3))&"-DEQ'!E8",TEXT(WEEKDAY(B7),"ddd")) -> Mon | C8: =HYPERLINK("#'"&UPPER(LEFT(TEXT($D$4,"mmmm"),3))&"-DEQ'!E15",TEXT(WEEKDAY(C7),"ddd")) -> Tue | D8: =HYPERLINK("#'"&UPPER(LEFT(TEXT($D$4,"mmmm"),3))&"-DEQ'!E22",TEXT(WEEKDAY(D7),"ddd")) -> Wed | E8: =HYPERLINK("#'"&UPPER(LEFT(TEXT($D$4,"mmmm"),3))&"-DEQ'!E29",TEXT(WEEKDAY(E7),"ddd")) -> Thu | F8: =HYPERLINK("#'"&UPPER(LEFT(TEXT($D$4,"mmmm"),3))&"-DEQ'!E36",TEXT(WEEKDAY(F7),"ddd")) -> Fri | G8: =LEFT(TEXT(WEEKDAY(G7),"ddd"),1) -> S | H8: =LEFT(TEXT(WEEKDAY(H7),"ddd"),1) -> S | I8: =HYPERLINK("#'"&UPPER(LEFT(TEXT($D$4,"mmmm"),3))&"-DEQ'!E43",TEXT(WEEKDAY(I7),"ddd")) -> Mon | J8: =HYPERLINK("#'"&UPPER(LEFT(TEXT($D$4,"mmmm"),3))&"-DEQ'!E50",TEXT(WEEKDAY(J7),"ddd")) -> Tue | K8: =HYPERLINK("#'"&UPPER(LEFT(TEXT($D$4,"mmmm"),3))&"-DEQ'!E57",TEXT(WEEKDAY(K7),"ddd")) -> Wed | L8: =HYPERLINK("#'"&UPPER(LEFT(TEXT($D$4,"mmmm"),3))&"-DEQ'!E64",TEXT(WEEKDAY(L7),"ddd")) -> Thu | M8: =HYPERLINK("#'"&UPPER(LEFT(TEXT($D$4,"mmmm"),3))&"-DEQ'!E71",TEXT(WEEKDAY(M7),"ddd")) -> Fri | N8: =LEFT(TEXT(WEEKDAY(N7),"ddd"),1) -> S | O8: =LEFT(TEXT(WEEKDAY(O7),"ddd"),1) -> S | P8: =HYPERLINK("#'"&UPPER(LEFT(TEXT($D$4,"mmmm"),3))&"-DEQ'!E78",TEXT(WEEKDAY(P7),"ddd")) -> Mon | Q8: =HYPERLINK("#'"&UPPER(LEFT(TEXT($D$4,"mmmm"),3))&"-DEQ'!E85",TEXT(WEEKDAY(Q7),"ddd")) -> Tue | R8: =HYPERLINK("#'"&UPPER(LEFT(TEXT($D$4,"mmmm"),3))&"-DEQ'!E92",TEXT(WEEKDAY(R7),"ddd")) -> Wed | S8: =HYPERLINK("#'"&UPPER(LEFT(TEXT($D$4,"mmmm"),3))&"-DEQ'!E99",TEXT(WEEKDAY(S7),"ddd")) -> Thu | T8: =HYPERLINK("#'"&UPPER(LEFT(TEXT($D$4,"mmmm"),3))&"-DEQ'!E106",TEXT(WEEKDAY(T7),"ddd")) -> Fri | U8: =LEFT(TEXT(WEEKDAY(U7),"ddd"),1) -> S | V8: =LEFT(TEXT(WEEKDAY(V7),"ddd"),1) -> S | W8: =HYPERLINK("#'"&UPPER(LEFT(TEXT($D$4,"mmmm"),3))&"-DEQ'!E113",TEXT(WEEKDAY(W7),"ddd")) -> Mon | X8: =HYPERLINK("#'"&UPPER(LEFT(TEXT($D$4,"mmmm"),3))&"-DEQ'!E120",TEXT(WEEKDAY(X7),"ddd")) -> Tue | Y8: =HYPERLINK("#'"&UPPER(LEFT(TEXT($D$4,"mmmm"),3))&"-DEQ'!E127",TEXT(WEEKDAY(Y7),"ddd")) -> Wed | Z8: =HYPERLINK("#'"&UPPER(LEFT(TEXT($D$4,"mmmm"),3))&"-DEQ'!E134",TEXT(WEEKDAY(Z7),"ddd")) -> Thu | AA8: =HYPERLINK("#'"&UPPER(LEFT(TEXT($D$4,"mmmm"),3))&"-DEQ'!E141",TEXT(WEEKDAY(AA7),"ddd")) -> Fri | AB8: =LEFT(TEXT(WEEKDAY(AB7),"ddd"),1) -> S | AC8: =LEFT(TEXT(WEEKDAY(AC7),"ddd"),1) -> S | AD8: =HYPERLINK("#'"&UPPER(LEFT(TEXT($D$4,"mmmm"),3))&"-DEQ'!E149",TEXT(WEEKDAY(AD7),"ddd")) -> Mon | AE8: =HYPERLINK("#'"&UPPER(LEFT(TEXT($D$4,"mmmm"),3))&"-DEQ'!E155",TEXT(WEEKDAY(AE7),"ddd")) -> Tue | AF8: =HYPERLINK("#'"&UPPER(LEFT(TEXT($D$4,"mmmm"),3))&"-DEQ'!E162",TEXT(WEEKDAY(AF7),"ddd")) -> Wed | AG8: =HYPERLINK("#'"&UPPER(LEFT(TEXT($D$4,"mmmm"),3))&"-DEQ'!E169",TEXT(WEEKDAY(AG7),"ddd")) -> Thu | AH8: =HYPERLINK("#'"&UPPER(LEFT(TEXT($D$4,"mmmm"),3))&"-DEQ'!E176",TEXT(WEEKDAY(AH7),"ddd")) -> Fri
A9: Hours
A10: ='Yearly Info'!A13 -> Enter Job #s on Yearly Info Tab
A11: ='Yearly Info'!A14 -> RICS Support for MDEQ | F11: 0.5 | J11: 0.5 | K11: 0.25 | L11: 0.5 | M11: 0.5 | T11: 0.5 | AD11: 0.25 | AI11: =SUM(B11:AH11) -> 3
A12: ='Yearly Info'!#REF! -> #REF! | E12: 0.25 | I12: 1.5 | Q12: 0.25 | X12: 1.75 | AI12: =SUM(B12:AH12) -> 3.75
A13: ='Yearly Info'!A15 -> MDEQ | C13: 1.5 | D13: 0.5 | E13: 0.25 | M13: 0.75 | Q13: 0.25 | R13: 0.5 | S13: 0.75 | T13: 0.75 | W13: 0.75 | Y13: 2.75 | Z13: 0.25 | AA13: 0.25 | AD13: 0.75 | AE13: 0.5 | AI13: =SUM(B13:AH13) -> 10.5
A14: ='Yearly Info'!A16 -> RICS Idea Portal | E14: 1 | K14: 1.5 | L14: 0.75 | M14: 0.25 | S14: 1 | T14: 0.25 | Z14: 1 | AI14: =SUM(B14:AH14) -> 5.75
A15: ='Yearly Info'!A17 -> MSWIS | C15: 1 | D15: 0.75 | E15: 1 | F15: 0.25 | M15: 0.75 | Q15: 0.75 | T15: 1.5 | AA15: 1.25 | AD15: 0.25 | AE15: 0.5 | AI15: =SUM(B15:AH15) -> 8
A16: ='Yearly Info'!A18 -> GeoSpatial | C16: 1.75 | D16: 1 | E16: 1.5 | F16: 4.75 | I16: 0.5 | J16: 1.5 | M16: 3.5 | Q16: 3.25 | R16: 0.5 | S16: 0.25 | T16: 2 | W16: 1.5 | X16: 1.5 | Z16: 0.75 | AA16: 2.5 | AD16: 0.75 | AE16: 1.25 | AI16: =SUM(B16:AH16) -> 28.75
A17: ='Yearly Info'!A19 -> RICS Dashboard | C17: 2.75 | D17: 1.75 | E17: 2.25 | F17: 1.75 | I17: 0.75 | J17: 3.75 | K17: 1.5 | L17: 1.25 | M17: 0.5 | Q17: 1.5 | R17: 2.5 | S17: 4.75 | T17: 2.75 | W17: 2.75 | X17: 1.25 | Y17: 1 | Z17: 0.5 | AA17: 0.75 | AD17: 1.75 | AE17: 2.25 | AI17: =SUM(B17:AH17) -> 38
A18: ='Yearly Info'!A20 -> MDWFP NRIS | I18: 1 | M18: 0.5 | Z18: 1 | AA18: 0.5 | AI18: =SUM(B18:AH18) -> 3
A19: ='Yearly Info'!A21 -> MSWIS MRVA 4 CLOSED | C19: 0.25 | E19: 0.25 | J19: 1 | K19: 0.25 | M19: 0.25 | S19: 0.5 | W19: 2.5 | X19: 0.75 | Y19: 2.25 | Z19: 0.5 | AA19: 1 | AD19: 1 | AE19: 0.5 | AI19: =SUM(B19:AH19) -> 11
A20: ='Yearly Info'!A22 -> Tackett | AI20: =SUM(B20:AH20) -> 0
A21: ='Yearly Info'!A23 -> 0 | D21: 1.25 | E21: 0.5 | F21: 0.5 | I21: 0.75 | J21: 0.5 | W21: 0.5 | X21: 1 | Y21: 1.5 | Z21: 2.25 | AI21: =SUM(B21:AH21) -> 8.75
A22: ='Yearly Info'!#REF! -> #REF! | C22: 0.25 | D22: 1.5 | M22: 0.25 | R22: 2 | S22: 0.75 | AD22: 0.25 | AE22: 0.25 | AI22: =SUM(B22:AH22) -> 5.25
A23: ='Yearly Info'!A24 -> 0 | D23: 1.25 | E23: 0.25 | F23: 0.25 | T23: 0.25 | X23: 1 | AA23: 0.25 | AD23: 0.5 | AE23: 1.5 | AI23: =SUM(B23:AH23) -> 5.25
A24: ='Yearly Info'!A25 -> 0 | M24: 0.5 | AE24: 0.5 | AI24: =SUM(B24:AH24) -> 1
A25: ='Yearly Info'!A26 -> 0 | M25: 0.25 | Z25: 1.75 | AA25: 1.5 | AD25: 2.5 | AE25: 0.75 | AI25: =SUM(B25:AH25) -> 6.75
A26: ='Yearly Info'!A27 -> 0 | C26: 0.5 | E26: 0.75 | J26: 0.75 | X26: 0.75 | AI26: =SUM(B26:AH26) -> 2.75
A27: ='Yearly Info'!A28 -> 0 | Y27: 0.5 | AI27: =SUM(B27:AH27) -> 0.5
A28: ='Yearly Info'!A29 -> 0 | AI28: =SUM(B28:AH28) -> 0
A29: ='Yearly Info'!A30 -> 0 | AI29: =SUM(B29:AH29) -> 0
A30: ='Yearly Info'!A31 -> 0 | AI30: =SUM(B30:AH30) -> 0
A31: ='Yearly Info'!A32 -> 0 | AI31: =SUM(B31:AH31) -> 0
A32: ='Yearly Info'!A33 -> 0 | AI32: =SUM(B32:AH32) -> 0
A33: Total | B33: =SUM(B9:B32) -> 0 | C33: =SUM(C9:C32) -> 8 | D33: =SUM(D9:D32) -> 8 | E33: =SUM(E9:E32) -> 8 | F33: =SUM(F9:F32) -> 8 | G33: =SUM(G9:G32) -> 0 | H33: =SUM(H9:H32) -> 0 | I33: =SUM(I9:I32) -> 4.5 | ... AH33: =SUM(AH9:AH32) -> 0 | AI33: =SUM(AI11:AI32) -> 142
A34: Leave - Holiday | B34: =IF(B7<$D$4,0, IF(B7='Yearly Info'!$C2, 8, IF(B7='Yearly Info'!$C3, 8, IF(B7='Yearly Info'!$C4, 8, IF(B7='Yearly Info'!$C5, 8, IF(B7='Yearly Info'!$C6, 8, IF(B7='Yearly Info'!$C7, 8, IF(B7='Yearly Info'!$C8, 8, IF(B7='Yearly Info'!$C9, 8, IF(B7='Yearly Info'!$C10, 8, IF(B7='Yearly Info'!$C11,8,0))))))))))) -> 0 | C34: =IF(C7<$D$4,0, IF(C7='Yearly Info'!$C2, 8, IF(C7='Yearly Info'!$C3, 8, IF(C7='Yearly Info'!$C4, 8, IF(C7='Yearly Info'!$C5, 8, IF(C7='Yearly Info'!$C6, 8, IF(C7='Yearly Info'!$C7, 8, IF(C7='Yearly Info'!$C8, 8, IF(C7='Yearly Info'!$C9, 8, IF(C7='Yearly Info'!$C10, 8, IF(C7='Yearly Info'!$C11,8,0))))))))))) -> 0 | D34: =IF(D7<$D$4,0, IF(D7='Yearly Info'!$C2, 8, IF(D7='Yearly Info'!$C3, 8, IF(D7='Yearly Info'!$C4, 8, IF(D7='Yearly Info'!$C5, 8, IF(D7='Yearly Info'!$C6, 8, IF(D7='Yearly Info'!$C7, 8, IF(D7='Yearly Info'!$C8, 8, IF(D7='Yearly Info'!$C9, 8, IF(D7='Yearly Info'!$C10, 8, IF(D7='Yearly Info'!$C11,8,0))))))))))) -> 0 | E34: =IF(E7<$D$4,0, IF(E7='Yearly Info'!$C2, 8, IF(E7='Yearly Info'!$C3, 8, IF(E7='Yearly Info'!$C4, 8, IF(E7='Yearly Info'!$C5, 8, IF(E7='Yearly Info'!$C6, 8, IF(E7='Yearly Info'!$C7, 8, IF(E7='Yearly Info'!$C8, 8, IF(E7='Yearly Info'!$C9, 8, IF(E7='Yearly Info'!$C10, 8, IF(E7='Yearly Info'!$C11,8,0))))))))))) -> 8 | F34: =IF(F7<$D$4,0, IF(F7='Yearly Info'!$C2, 8, IF(F7='Yearly Info'!$C3, 8, IF(F7='Yearly Info'!$C4, 8, IF(F7='Yearly Info'!$C5, 8, IF(F7='Yearly Info'!$C6, 8, IF(F7='Yearly Info'!$C7, 8, IF(F7='Yearly Info'!$C8, 8, IF(F7='Yearly Info'!$C9, 8, IF(F7='Yearly Info'!$C10, 8, IF(F7='Yearly Info'!$C11,8,0))))))))))) -> 0 | G34: =IF(G7='Yearly Info'!$C2, 8, IF(G7='Yearly Info'!$C3, 8, IF(G7='Yearly Info'!$C4, 8, IF(G7='Yearly Info'!$C5, 8, IF(G7='Yearly Info'!$C6, 8, IF(G7='Yearly Info'!$C7, 8, IF(G7='Yearly Info'!$C8, 8, IF(G7='Yearly Info'!$C9, 8, IF(G7='Yearly Info'!$C10, 8, IF(G7='Yearly Info'!$C11,8,0)))))))))) -> 0 | H34: =IF(H7='Yearly Info'!$C2, 8, IF(H7='Yearly Info'!$C3, 8, IF(H7='Yearly Info'!$C4, 8, IF(H7='Yearly Info'!$C5, 8, IF(H7='Yearly Info'!$C6, 8, IF(H7='Yearly Info'!$C7, 8, IF(H7='Yearly Info'!$C8, 8, IF(H7='Yearly Info'!$C9, 8, IF(H7='Yearly Info'!$C10, 8, IF(H7='Yearly Info'!$C11,8,0)))))))))) -> 0 | I34: =IF(I7='Yearly Info'!$C2, 8, IF(I7='Yearly Info'!$C3, 8, IF(I7='Yearly Info'!$C4, 8, IF(I7='Yearly Info'!$C5, 8, IF(I7='Yearly Info'!$C6, 8, IF(I7='Yearly Info'!$C7, 8, IF(I7='Yearly Info'!$C8, 8, IF(I7='Yearly Info'!$C9, 8, IF(I7='Yearly Info'!$C10, 8, IF(I7='Yearly Info'!$C11,8,0)))))))))) -> 0 | J34: =IF(J7='Yearly Info'!$C2, 8, IF(J7='Yearly Info'!$C3, 8, IF(J7='Yearly Info'!$C4, 8, IF(J7='Yearly Info'!$C5, 8, IF(J7='Yearly Info'!$C6, 8, IF(J7='Yearly Info'!$C7, 8, IF(J7='Yearly Info'!$C8, 8, IF(J7='Yearly Info'!$C9, 8, IF(J7='Yearly Info'!$C10, 8, IF(J7='Yearly Info'!$C11,8,0)))))))))) -> 0 | K34: =IF(K7='Yearly Info'!$C2, 8, IF(K7='Yearly Info'!$C3, 8, IF(K7='Yearly Info'!$C4, 8, IF(K7='Yearly Info'!$C5, 8, IF(K7='Yearly Info'!$C6, 8, IF(K7='Yearly Info'!$C7, 8, IF(K7='Yearly Info'!$C8, 8, IF(K7='Yearly Info'!$C9, 8, IF(K7='Yearly Info'!$C10, 8, IF(K7='Yearly Info'!$C11,8,0)))))))))) -> 0 | L34: =IF(L7='Yearly Info'!$C2, 8, IF(L7='Yearly Info'!$C3, 8, IF(L7='Yearly Info'!$C4, 8, IF(L7='Yearly Info'!$C5, 8, IF(L7='Yearly Info'!$C6, 8, IF(L7='Yearly Info'!$C7, 8, IF(L7='Yearly Info'!$C8, 8, IF(L7='Yearly Info'!$C9, 8, IF(L7='Yearly Info'!$C10, 8, IF(L7='Yearly Info'!$C11,8,0)))))))))) -> 0 | M34: =IF(M7='Yearly Info'!$C2, 8, IF(M7='Yearly Info'!$C3, 8, IF(M7='Yearly Info'!$C4, 8, IF(M7='Yearly Info'!$C5, 8, IF(M7='Yearly Info'!$C6, 8, IF(M7='Yearly Info'!$C7, 8, IF(M7='Yearly Info'!$C8, 8, IF(M7='Yearly Info'!$C9, 8, IF(M7='Yearly Info'!$C10, 8, IF(M7='Yearly Info'!$C11,8,0)))))))))) -> 0 | N34: =IF(N7='Yearly Info'!$C2, 8, IF(N7='Yearly Info'!$C3, 8, IF(N7='Yearly Info'!$C4, 8, IF(N7='Yearly Info'!$C5, 8, IF(N7='Yearly Info'!$C6, 8, IF(N7='Yearly Info'!$C7, 8, IF(N7='Yearly Info'!$C8, 8, IF(N7='Yearly Info'!$C9, 8, IF(N7='Yearly Info'!$C10, 8, IF(N7='Yearly Info'!$C11,8,0)))))))))) -> 0 | ... AA34: =IF(AA7='Yearly Info'!$C2, 8, IF(AA7='Yearly Info'!$C3, 8, IF(AA7='Yearly Info'!$C4, 8, IF(AA7='Yearly Info'!$C5, 8, IF(AA7='Yearly Info'!$C6, 8, IF(AA7='Yearly Info'!$C7, 8, IF(AA7='Yearly Info'!$C8, 8, IF(AA7='Yearly Info'!$C9, 8, IF(AA7='Yearly Info'!$C10, 8, IF(AA7='Yearly Info'!$C11,8,0)))))))))) -> 0 | AB34: =IF(AB7>EOMONTH($D$4,0),0, IF(AB7='Yearly Info'!$C2, 8, IF(AB7='Yearly Info'!$C3, 8, IF(AB7='Yearly Info'!$C4, 8, IF(AB7='Yearly Info'!$C5, 8, IF(AB7='Yearly Info'!$C6, 8, IF(AB7='Yearly Info'!$C7, 8, IF(AB7='Yearly Info'!$C8, 8, IF(AB7='Yearly Info'!$C9, 8, IF(AB7='Yearly Info'!$C10, 8, IF(AB7='Yearly Info'!$C11,8,0))))))))))) -> 0 | AC34: =IF(AC7>EOMONTH($D$4,0),0, IF(AC7='Yearly Info'!$C2, 8, IF(AC7='Yearly Info'!$C3, 8, IF(AC7='Yearly Info'!$C4, 8, IF(AC7='Yearly Info'!$C5, 8, IF(AC7='Yearly Info'!$C6, 8, IF(AC7='Yearly Info'!$C7, 8, IF(AC7='Yearly Info'!$C8, 8, IF(AC7='Yearly Info'!$C9, 8, IF(AC7='Yearly Info'!$C10, 8, IF(AC7='Yearly Info'!$C11,8,0))))))))))) -> 0 | AE34: =IF(AE7>EOMONTH($D$4,0),0, IF(AE7='Yearly Info'!$C2, 8, IF(AE7='Yearly Info'!$C3, 8, IF(AE7='Yearly Info'!$C4, 8, IF(AE7='Yearly Info'!$C5, 8, IF(AE7='Yearly Info'!$C6, 8, IF(AE7='Yearly Info'!$C7, 8, IF(AE7='Yearly Info'!$C8, 8, IF(AE7='Yearly Info'!$C9, 8, IF(AE7='Yearly Info'!$C10, 8, IF(AE7='Yearly Info'!$C11,8,0))))))))))) -> 0 | AF34: =IF(AF7>EOMONTH($D$4,0),0, IF(AF7='Yearly Info'!$C2, 8, IF(AF7='Yearly Info'!$C3, 8, IF(AF7='Yearly Info'!$C4, 8, IF(AF7='Yearly Info'!$C5, 8, IF(AF7='Yearly Info'!$C6, 8, IF(AF7='Yearly Info'!$C7, 8, IF(AF7='Yearly Info'!$C8, 8, IF(AF7='Yearly Info'!$C9, 8, IF(AF7='Yearly Info'!$C10, 8, IF(AF7='Yearly Info'!$C11,8,0))))))))))) -> 0 | AG34: =IF(AG7>EOMONTH($D$4,0),0, IF(AG7='Yearly Info'!$C2, 8, IF(AG7='Yearly Info'!$C3, 8, IF(AG7='Yearly Info'!$C4, 8, IF(AG7='Yearly Info'!$C5, 8, IF(AG7='Yearly Info'!$C6, 8, IF(AG7='Yearly Info'!$C7, 8, IF(AG7='Yearly Info'!$C8, 8, IF(AG7='Yearly Info'!$C9, 8, IF(AG7='Yearly Info'!$C10, 8, IF(AG7='Yearly Info'!$C11,8,0))))))))))) -> 0 | AH34: =IF(AH7>EOMONTH($D$4,0),0, IF(AH7='Yearly Info'!$C2, 8, IF(AH7='Yearly Info'!$C3, 8, IF(AH7='Yearly Info'!$C4, 8, IF(AH7='Yearly Info'!$C5, 8, IF(AH7='Yearly Info'!$C6, 8, IF(AH7='Yearly Info'!$C7, 8, IF(AH7='Yearly Info'!$C8, 8, IF(AH7='Yearly Info'!$C9, 8, IF(AH7='Yearly Info'!$C10, 8, IF(AH7='Yearly Info'!$C11,8,0))))))))))) -> 0 | AI34: =SUM(B34:AH34) -> 16
B35: Leave - Personal | AI35: =IF(SUM(B39:AH39)-AI33-AI34>0,SUM(B39:AH39)-AI33-AI34,0) -> 18
B36: Extended Work Week (Extra Hours) | AI36: =IF(SUM(B39:AH39)-AI33-AI34<0,(SUM(B39:AH39)-AI33-AI34)*-1,0) -> 0
A37: Daily Total | B37: =SUM(B36,B34,B33) -> 0 | C37: =SUM(C36,C34,C33) -> 8 | D37: =SUM(D36,D34,D33) -> 8 | E37: =SUM(E36,E34,E33) -> 16 | F37: =SUM(F36,F34,F33) -> 8 | G37: =SUM(G36,G34,G33) -> 0 | H37: =SUM(H36,H34,H33) -> 0 | I37: =SUM(I36,I34,I33) -> 4.5 | ... AH37: =SUM(AH36,AH34,AH33) -> 0 | AI37: =SUM(B37:AH37) -> 158
A38: Weekly Total | B38: =IF(B8="Sun",SUM(B37),"") | C38: =IF(C8="Sun",SUM(B37,C37),"") | D38: =IF(D8="Sun",SUM(B37,C37,D37),"") | E38: =IF(E8="Sun",SUM(B37,C37,D37,E37),"") | F38: =SUM(B37:H37) -> 40 | I38: =IF(I8="Sun",SUM(C37,D37,E37,F37,G37,H37,I37),"") | J38: =IF(J8="Sun",SUM(D37,E37,F37,G37,H37,I37,J37),"") | K38: =IF(K8="Sun",SUM(E37,F37,G37,H37,I37,J37,K37),"") | L38: =IF(L8="Sun",SUM(F37,G37,H37,I37,J37,K37,L37),"") | M38: =SUM(I37:O37) -> 26.5 | P38: =IF(P8="Sun",SUM(J37,K37,L37,M37,N37,O37,P37),"") | Q38: =IF(Q8="Sun",SUM(K37,L37,M37,N37,O37,P37,Q37),"") | R38: =IF(R8="Sun",SUM(L37,M37,N37,O37,P37,Q37,R37),"") | S38: =IF(S8="Sun",SUM(M37,N37,O37,P37,Q37,R37,S37),"") | T38: =SUM(P37:V37) -> 27.5 | W38: =IF(W8="Sun",SUM(Q37,R37,S37,T37,U37,V37,W37),"") | X38: =IF(X8="Sun",SUM(R37,S37,T37,U37,V37,W37,X37),"") | Y38: =IF(Y8="Sun",SUM(S37,T37,U37,V37,W37,X37,Y37),"") | Z38: =IF(Z8="Sun",SUM(T37,U37,V37,W37,X37,Y37,Z37),"") | AA38: =SUM(W37:AC37) -> 48 | AD38: =IF(AD8="Sun",SUM(X37,Y37,Z37,AA37,AB37,AC37,AD37),"") | AE38: =IF(AE8="Sun",SUM(Y37,Z37,AA37,AB37,AC37,AD37,AE37),"") | AF38: =IF(AF8="Sun",SUM(Z37,AA37,AB37,AC37,AD37,AE37,AF37),"") | AG38: =IF(AG8="Sun",SUM(AA37,AB37,AC37,AD37,AE37,AF37,AG37),"") | AH38: =SUM(AD37:AH37) -> 16 | AI38: =SUM(B38:AH38) -> 158
B39: =IF(B7>=$D$4,IF(B7<=EOMONTH($D$4,0), IF(B8="S",0,IF(B8="S",0,8)),0),0) -> 0 | C39: =IF(C7>=$D$4,IF(C7<=EOMONTH($D$4,0), IF(C8="S",0,IF(C8="S",0,8)),0),0) -> 0 | D39: =IF(D7>=$D$4,IF(D7<=EOMONTH($D$4,0), IF(D8="S",0,IF(D8="S",0,8)),0),0) -> 0 | E39: =IF(E7>=$D$4,IF(E7<=EOMONTH($D$4,0), IF(E8="S",0,IF(E8="S",0,8)),0),0) -> 8 | F39: =IF(F7>=$D$4,IF(F7<=EOMONTH($D$4,0), IF(F8="S",0,IF(F8="S",0,8)),0),0) -> 8 | G39: =IF(G7>=$D$4,IF(G7<=EOMONTH($D$4,0), IF(G8="S",0,IF(G8="S",0,8)),0),0) -> 0 | H39: =IF(H7>=$D$4,IF(H7<=EOMONTH($D$4,0), IF(H8="S",0,IF(H8="S",0,8)),0),0) -> 0 | I39: =IF(I7>=$D$4,IF(I7<=EOMONTH($D$4,0), IF(I8="S",0,IF(I8="S",0,8)),0),0) -> 8 | ... AH39: =IF(AH7>=$D$4,IF(AH7<=EOMONTH($D$4,0), IF(AH8="S",0,IF(AH8="S",0,8)),0),0) -> 8 | AI39: =SUM(B39:AH39) -> 176
B44: MONTHLY TIME RECORD For MDEQ
B45: Name: | D45: =D3 -> Don Woods
B46: Month: | D46: =D4 -> 46023 | J46: Year: | L46: =L4 -> 2026
...

Sheet JAN
B2: MONTHLY TIME RECORD
B3: Name: | D3: ='Yearly Info'!A45 -> Don Woods
B4: Month: | D4: ='Yearly Info'!D1 -> 46023 | J4: Year: | L4: ='Yearly Info'!B1 -> 2026
A6: Project No. & Description | B6: Day of the Month | AI6: Total Hours
B7: =IF(WEEKDAY(D$4,2)>5,D$4+8 - WEEKDAY(D$4,2),D$4-(WEEKDAY(D$4,2)-1)) -> 46020 | C7: =B7+1 -> 46021 | D7: =C7+1 -> 46022 | E7: =D7+1 -> 46023 | F7: =E7+1 -> 46024 | G7: =F7+1 -> 46025 | H7: =G7+1 -> 46026 | I7: =H7+1 -> 46027 | J7: =I7+1 -> 46028 | ... AH7: =AG7+1 -> 46052 | AI7: Hours
B8: =HYPERLINK("#'"&UPPER(LEFT(TEXT($D$4,"mmmm"),3))&"-DEQ'!E8",TEXT(WEEKDAY(B7),"ddd")) -> Mon | C8: =HYPERLINK("#'"&UPPER(LEFT(TEXT($D$4,"mmmm"),3))&"-DEQ'!E15",TEXT(WEEKDAY(C7),"ddd")) -> Tue | D8: =HYPERLINK("#'"&UPPER(LEFT(TEXT($D$4,"mmmm"),3))&"-DEQ'!E22",TEXT(WEEKDAY(D7),"ddd")) -> Wed | E8: =HYPERLINK("#'"&UPPER(LEFT(TEXT($D$4,"mmmm"),3))&"-DEQ'!E29",TEXT(WEEKDAY(E7),"ddd")) -> Thu | F8: =HYPERLINK("#'"&UPPER(LEFT(TEXT($D$4,"mmmm"),3))&"-DEQ'!E36",TEXT(WEEKDAY(F7),"ddd")) -> Fri | G8: =LEFT(TEXT(WEEKDAY(G7),"ddd"),1) -> S | H8: =LEFT(TEXT(WEEKDAY(H7),"ddd"),1) -> S | I8: =HYPERLINK("#'"&UPPER(LEFT(TEXT($D$4,"mmmm"),3))&"-DEQ'!E43",TEXT(WEEKDAY(I7),"ddd")) -> Mon | J8: =HYPERLINK("#'"&UPPER(LEFT(TEXT($D$4,"mmmm"),3))&"-DEQ'!E50",TEXT(WEEKDAY(J7),"ddd")) -> Tue | K8: =HYPERLINK("#'"&UPPER(LEFT(TEXT($D$4,"mmmm"),3))&"-DEQ'!E57",TEXT(WEEKDAY(K7),"ddd")) -> Wed | L8: =HYPERLINK("#'"&UPPER(LEFT(TEXT($D$4,"mmmm"),3))&"-DEQ'!E64",TEXT(WEEKDAY(L7),"ddd")) -> Thu | M8: =HYPERLINK("#'"&UPPER(LEFT(TEXT($D$4,"mmmm"),3))&"-DEQ'!E71",TEXT(WEEKDAY(M7),"ddd")) -> Fri | N8: =LEFT(TEXT(WEEKDAY(N7),"ddd"),1) -> S | O8: =LEFT(TEXT(WEEKDAY(O7),"ddd"),1) -> S | P8: =HYPERLINK("#'"&UPPER(LEFT(TEXT($D$4,"mmmm"),3))&"-DEQ'!E78",TEXT(WEEKDAY(P7),"ddd")) -> Mon | Q8: =HYPERLINK("#'"&UPPER(LEFT(TEXT($D$4,"mmmm"),3))&"-DEQ'!E85",TEXT(WEEKDAY(Q7),"ddd")) -> Tue | R8: =HYPERLINK("#'"&UPPER(LEFT(TEXT($D$4,"mmmm"),3))&"-DEQ'!E92",TEXT(WEEKDAY(R7),"ddd")) -> Wed | S8: =HYPERLINK("#'"&UPPER(LEFT(TEXT($D$4,"mmmm"),3))&"-DEQ'!E99",TEXT(WEEKDAY(S7),"ddd")) -> Thu | T8: =HYPERLINK("#'"&UPPER(LEFT(TEXT($D$4,"mmmm"),3))&"-DEQ'!E106",TEXT(WEEKDAY(T7),"ddd")) -> Fri | U8: =LEFT(TEXT(WEEKDAY(U7),"ddd"),1) -> S | V8: =LEFT(TEXT(WEEKDAY(V7),"ddd"),1) -> S | W8: =HYPERLINK("#'"&UPPER(LEFT(TEXT($D$4,"mmmm"),3))&"-DEQ'!E113",TEXT(WEEKDAY(W7),"ddd")) -> Mon | X8: =HYPERLINK("#'"&UPPER(LEFT(TEXT($D$4,"mmmm"),3))&"-DEQ'!E120",TEXT(WEEKDAY(X7),"ddd")) -> Tue | Y8: =HYPERLINK("#'"&UPPER(LEFT(TEXT($D$4,"mmmm"),3))&"-DEQ'!E127",TEXT(WEEKDAY(Y7),"ddd")) -> Wed | Z8: =HYPERLINK("#'"&UPPER(LEFT(TEXT($D$4,"mmmm"),3))&"-DEQ'!E134",TEXT(WEEKDAY(Z7),"ddd")) -> Thu | AA8: =HYPERLINK("#'"&UPPER(LEFT(TEXT($D$4,"mmmm"),3))&"-DEQ'!E141",TEXT(WEEKDAY(AA7),"ddd")) -> Fri | AB8: =LEFT(TEXT(WEEKDAY(AB7),"ddd"),1) -> S | AC8: =LEFT(TEXT(WEEKDAY(AC7),"ddd"),1) -> S | AD8: =HYPERLINK("#'"&UPPER(LEFT(TEXT($D$4,"mmmm"),3))&"-DEQ'!E149",TEXT(WEEKDAY(AD7),"ddd")) -> Mon | AE8: =HYPERLINK("#'"&UPPER(LEFT(TEXT($D$4,"mmmm"),3))&"-DEQ'!E155",TEXT(WEEKDAY(AE7),"ddd")) -> Tue | AF8: =HYPERLINK("#'"&UPPER(LEFT(TEXT($D$4,"mmmm"),3))&"-DEQ'!E162",TEXT(WEEKDAY(AF7),"ddd")) -> Wed | AG8: =HYPERLINK("#'"&UPPER(LEFT(TEXT($D$4,"mmmm"),3))&"-DEQ'!E169",TEXT(WEEKDAY(AG7),"ddd")) -> Thu | AH8: =HYPERLINK("#'"&UPPER(LEFT(TEXT($D$4,"mmmm"),3))&"-DEQ'!E176",TEXT(WEEKDAY(AH7),"ddd")) -> Fri
A9: Hours
A10: ='Yearly Info'!A13 -> Enter Job #s on Yearly Info Tab
A11: ='Yearly Info'!A14 -> RICS Support for MDEQ | AG11: 4 | AI11: =SUM(B11:AH11) -> 4
A12: ='Yearly Info'!A15 -> MDEQ | AI12: =SUM(B12:AH12) -> 0
A13: ='Yearly Info'!A16 -> RICS Idea Portal | S13: 4 | AI13: =SUM(B13:AH13) -> 4
A14: ='Yearly Info'!A17 -> MSWIS | I14: 5 | J14: 6 | K14: 8 | L14: 8 | M14: 2 | P14: 3 | Q14: 3 | R14: 2 | S14: 4 | X14: 4 | Y14: 3 | AD14: 8 | AE14: 2 | AF14: 4 | AG14: 4 | AI14: =SUM(B14:AH14) -> 66
A15: ='Yearly Info'!A18 -> GeoSpatial | AI15: =SUM(B15:AH15) -> 0
A16: ='Yearly Info'!A19 -> RICS Dashboard | AI16: =SUM(B16:AH16) -> 0
A17: ='Yearly Info'!A20 -> MDWFP NRIS | F17: 6 | I17: 5 | J17: 2 | K17: 2 | M17: 8 | T17: 2 | AE17: 2 | AI17: =SUM(B17:AH17) -> 27
A18: ='Yearly Info'!A21 -> MSWIS MRVA 4 CLOSED | J18: 2 | M18: 2 | P18: 5 | Q18: 5 | R18: 6 | T18: 6 | X18: 4 | Y18: 9 | Z18: 10 | AA18: 5 | AE18: 4 | AF18: 4 | AH18: 4.5 | AI18: =SUM(B18:AH18) -> 66.5
A19: ='Yearly Info'!A22 -> Tackett | AI19: =SUM(B19:AH19) -> 0
A20: ='Yearly Info'!A23 -> 0 | AI20: =SUM(B20:AH20) -> 0
A21: ='Yearly Info'!A24 -> 0 | AI21: =SUM(B21:AH21) -> 0
A22: ='Yearly Info'!A25 -> 0 | AI22: =SUM(B22:AH22) -> 0
A23: ='Yearly Info'!A26 -> 0 | AI23: =SUM(B23:AH23) -> 0
A24: ='Yearly Info'!A27 -> 0 | AI24: =SUM(B24:AH24) -> 0
A25: ='Yearly Info'!A28 -> 0 | AI25: =SUM(B25:AH25) -> 0
A26: ='Yearly Info'!A29 -> 0 | AI26: =SUM(B26:AH26) -> 0
A27: ='Yearly Info'!A30 -> 0 | AI27: =SUM(B27:AH27) -> 0
A28: ='Yearly Info'!A31 -> 0 | AI28: =SUM(B28:AH28) -> 0
A29: ='Yearly Info'!A32 -> 0 | AI29: =SUM(B29:AH29) -> 0
A30: ='Yearly Info'!A33 -> 0 | AI30: =SUM(B30:AH30) -> 0
... A40: ='Yearly Info'!A43 | AI40: =SUM(B40:AH40) -> 0
AI41: =SUM(B41:AH41) -> 0
A42: Total | B42: =SUM(B9:B40) -> 0 | C42: =SUM(C9:C40) -> 0 | D42: =SUM(D9:D40) -> 0 | E42: =SUM(E9:E40) -> 0 | F42: =SUM(F9:F40) -> 6 | G42: =SUM(G9:G40) -> 0 | H42: =SUM(H9:H40) -> 0 | I42: =SUM(I9:I40) -> 10 | ... AE42: =SUM(AE9:AE40) -> 8 | AF42: =SUM(AF9:AF41) -> 8 | AG42: =SUM(AG9:AG40) -> 8 | AH42: =SUM(AH9:AH40) -> 4.5 | AI42: =SUM(AI11:AI41) -> 167.5
A43: Leave - Holiday | B43: =IF(B7<$D$4,0, IF(B7='Yearly Info'!$C2, 8, IF(B7='Yearly Info'!$C3, 8, IF(B7='Yearly Info'!$C4, 8, IF(B7='Yearly Info'!$C5, 8, IF(B7='Yearly Info'!$C6, 8, IF(B7='Yearly Info'!$C7, 8, IF(B7='Yearly Info'!$C8, 8, IF(B7='Yearly Info'!$C9, 8, IF(B7='Yearly Info'!$C10, 8, IF(B7='Yearly Info'!$C11,8,0))))))))))) -> 0 | C43: =IF(C7<$D$4,0, IF(C7='Yearly Info'!$C2, 8, IF(C7='Yearly Info'!$C3, 8, IF(C7='Yearly Info'!$C4, 8, IF(C7='Yearly Info'!$C5, 8, IF(C7='Yearly Info'!$C6, 8, IF(C7='Yearly Info'!$C7, 8, IF(C7='Yearly Info'!$C8, 8, IF(C7='Yearly Info'!$C9, 8, IF(C7='Yearly Info'!$C10, 8, IF(C7='Yearly Info'!$C11,8,0))))))))))) -> 0 | D43: =IF(D7<$D$4,0, IF(D7='Yearly Info'!$C2, 8, IF(D7='Yearly Info'!$C3, 8, IF(D7='Yearly Info'!$C4, 8, IF(D7='Yearly Info'!$C5, 8, IF(D7='Yearly Info'!$C6, 8, IF(D7='Yearly Info'!$C7, 8, IF(D7='Yearly Info'!$C8, 8, IF(D7='Yearly Info'!$C9, 8, IF(D7='Yearly Info'!$C10, 8, IF(D7='Yearly Info'!$C11,8,0))))))))))) -> 0 | E43: =IF(E7<$D$4,0, IF(E7='Yearly Info'!$C2, 8, IF(E7='Yearly Info'!$C3, 8, IF(E7='Yearly Info'!$C4, 8, IF(E7='Yearly Info'!$C5, 8, IF(E7='Yearly Info'!$C6, 8, IF(E7='Yearly Info'!$C7, 8, IF(E7='Yearly Info'!$C8, 8, IF(E7='Yearly Info'!$C9, 8, IF(E7='Yearly Info'!$C10, 8, IF(E7='Yearly Info'!$C11,8,0))))))))))) -> 8 | F43: =IF(F7<$D$4,0, IF(F7='Yearly Info'!$C2, 8, IF(F7='Yearly Info'!$C3, 8, IF(F7='Yearly Info'!$C4, 8, IF(F7='Yearly Info'!$C5, 8, IF(F7='Yearly Info'!$C6, 8, IF(F7='Yearly Info'!$C7, 8, IF(F7='Yearly Info'!$C8, 8, IF(F7='Yearly Info'!$C9, 8, IF(F7='Yearly Info'!$C10, 8, IF(F7='Yearly Info'!$C11,8,0))))))))))) -> 0 | G43: =IF(G7='Yearly Info'!$C2, 8, IF(G7='Yearly Info'!$C3, 8, IF(G7='Yearly Info'!$C4, 8, IF(G7='Yearly Info'!$C5, 8, IF(G7='Yearly Info'!$C6, 8, IF(G7='Yearly Info'!$C7, 8, IF(G7='Yearly Info'!$C8, 8, IF(G7='Yearly Info'!$C9, 8, IF(G7='Yearly Info'!$C10, 8, IF(G7='Yearly Info'!$C11,8,0)))))))))) -> 0 | H43: =IF(H7='Yearly Info'!$C2, 8, IF(H7='Yearly Info'!$C3, 8, IF(H7='Yearly Info'!$C4, 8, IF(H7='Yearly Info'!$C5, 8, IF(H7='Yearly Info'!$C6, 8, IF(H7='Yearly Info'!$C7, 8, IF(H7='Yearly Info'!$C8, 8, IF(H7='Yearly Info'!$C9, 8, IF(H7='Yearly Info'!$C10, 8, IF(H7='Yearly Info'!$C11,8,0)))))))))) -> 0 | I43: =IF(I7='Yearly Info'!$C2, 8, IF(I7='Yearly Info'!$C3, 8, IF(I7='Yearly Info'!$C4, 8, IF(I7='Yearly Info'!$C5, 8, IF(I7='Yearly Info'!$C6, 8, IF(I7='Yearly Info'!$C7, 8, IF(I7='Yearly Info'!$C8, 8, IF(I7='Yearly Info'!$C9, 8, IF(I7='Yearly Info'!$C10, 8, IF(I7='Yearly Info'!$C11,8,0)))))))))) -> 0 | J43: =IF(J7='Yearly Info'!$C2, 8, IF(J7='Yearly Info'!$C3, 8, IF(J7='Yearly Info'!$C4, 8, IF(J7='Yearly Info'!$C5, 8, IF(J7='Yearly Info'!$C6, 8, IF(J7='Yearly Info'!$C7, 8, IF(J7='Yearly Info'!$C8, 8, IF(J7='Yearly Info'!$C9, 8, IF(J7='Yearly Info'!$C10, 8, IF(J7='Yearly Info'!$C11,8,0)))))))))) -> 0 | K43: =IF(K7='Yearly Info'!$C2, 8, IF(K7='Yearly Info'!$C3, 8, IF(K7='Yearly Info'!$C4, 8, IF(K7='Yearly Info'!$C5, 8, IF(K7='Yearly Info'!$C6, 8, IF(K7='Yearly Info'!$C7, 8, IF(K7='Yearly Info'!$C8, 8, IF(K7='Yearly Info'!$C9, 8, IF(K7='Yearly Info'!$C10, 8, IF(K7='Yearly Info'!$C11,8,0)))))))))) -> 0 | L43: =IF(L7='Yearly Info'!$C2, 8, IF(L7='Yearly Info'!$C3, 8, IF(L7='Yearly Info'!$C4, 8, IF(L7='Yearly Info'!$C5, 8, IF(L7='Yearly Info'!$C6, 8, IF(L7='Yearly Info'!$C7, 8, IF(L7='Yearly Info'!$C8, 8, IF(L7='Yearly Info'!$C9, 8, IF(L7='Yearly Info'!$C10, 8, IF(L7='Yearly Info'!$C11,8,0)))))))))) -> 0 | M43: =IF(M7='Yearly Info'!$C2, 8, IF(M7='Yearly Info'!$C3, 8, IF(M7='Yearly Info'!$C4, 8, IF(M7='Yearly Info'!$C5, 8, IF(M7='Yearly Info'!$C6, 8, IF(M7='Yearly Info'!$C7, 8, IF(M7='Yearly Info'!$C8, 8, IF(M7='Yearly Info'!$C9, 8, IF(M7='Yearly Info'!$C10, 8, IF(M7='Yearly Info'!$C11,8,0)))))))))) -> 0 | N43: =IF(N7='Yearly Info'!$C2, 8, IF(N7='Yearly Info'!$C3, 8, IF(N7='Yearly Info'!$C4, 8, IF(N7='Yearly Info'!$C5, 8, IF(N7='Yearly Info'!$C6, 8, IF(N7='Yearly Info'!$C7, 8, IF(N7='Yearly Info'!$C8, 8, IF(N7='Yearly Info'!$C9, 8, IF(N7='Yearly Info'!$C10, 8, IF(N7='Yearly Info'!$C11,8,0)))))))))) -> 0 | ... AA43: =IF(AA7='Yearly Info'!$C2, 8, IF(AA7='Yearly Info'!$C3, 8, IF(AA7='Yearly Info'!$C4, 8, IF(AA7='Yearly Info'!$C5, 8, IF(AA7='Yearly Info'!$C6, 8, IF(AA7='Yearly Info'!$C7, 8, IF(AA7='Yearly Info'!$C8, 8, IF(AA7='Yearly Info'!$C9, 8, IF(AA7='Yearly Info'!$C10, 8, IF(AA7='Yearly Info'!$C11,8,0)))))))))) -> 0 | AB43: =IF(AB7>EOMONTH($D$4,0),0, IF(AB7='Yearly Info'!$C2, 8, IF(AB7='Yearly Info'!$C3, 8, IF(AB7='Yearly Info'!$C4, 8, IF(AB7='Yearly Info'!$C5, 8, IF(AB7='Yearly Info'!$C6, 8, IF(AB7='Yearly Info'!$C7, 8, IF(AB7='Yearly Info'!$C8, 8, IF(AB7='Yearly Info'!$C9, 8, IF(AB7='Yearly Info'!$C10, 8, IF(AB7='Yearly Info'!$C11,8,0))))))))))) -> 0 | AC43: =IF(AC7>EOMONTH($D$4,0),0, IF(AC7='Yearly Info'!$C2, 8, IF(AC7='Yearly Info'!$C3, 8, IF(AC7='Yearly Info'!$C4, 8, IF(AC7='Yearly Info'!$C5, 8, IF(AC7='Yearly Info'!$C6, 8, IF(AC7='Yearly Info'!$C7, 8, IF(AC7='Yearly Info'!$C8, 8, IF(AC7='Yearly Info'!$C9, 8, IF(AC7='Yearly Info'!$C10, 8, IF(AC7='Yearly Info'!$C11,8,0))))))))))) -> 0 | AE43: =IF(AE7>EOMONTH($D$4,0),0, IF(AE7='Yearly Info'!$C2, 8, IF(AE7='Yearly Info'!$C3, 8, IF(AE7='Yearly Info'!$C4, 8, IF(AE7='Yearly Info'!$C5, 8, IF(AE7='Yearly Info'!$C6, 8, IF(AE7='Yearly Info'!$C7, 8, IF(AE7='Yearly Info'!$C8, 8, IF(AE7='Yearly Info'!$C9, 8, IF(AE7='Yearly Info'!$C10, 8, IF(AE7='Yearly Info'!$C11,8,0))))))))))) -> 0 | AF43: =IF(AF7>EOMONTH($D$4,0),0, IF(AF7='Yearly Info'!$C2, 8, IF(AF7='Yearly Info'!$C3, 8, IF(AF7='Yearly Info'!$C4, 8, IF(AF7='Yearly Info'!$C5, 8, IF(AF7='Yearly Info'!$C6, 8, IF(AF7='Yearly Info'!$C7, 8, IF(AF7='Yearly Info'!$C8, 8, IF(AF7='Yearly Info'!$C9, 8, IF(AF7='Yearly Info'!$C10, 8, IF(AF7='Yearly Info'!$C11,8,0))))))))))) -> 0 | AG43: =IF(AG7>EOMONTH($D$4,0),0, IF(AG7='Yearly Info'!$C2, 8, IF(AG7='Yearly Info'!$C3, 8, IF(AG7='Yearly Info'!$C4, 8, IF(AG7='Yearly Info'!$C5, 8, IF(AG7='Yearly Info'!$C6, 8, IF(AG7='Yearly Info'!$C7, 8, IF(AG7='Yearly Info'!$C8, 8, IF(AG7='Yearly Info'!$C9, 8, IF(AG7='Yearly Info'!$C10, 8, IF(AG7='Yearly Info'!$C11,8,0))))))))))) -> 0 | AH43: =IF(AH7>EOMONTH($D$4,0),0, IF(AH7='Yearly Info'!$C2, 8, IF(AH7='Yearly Info'!$C3, 8, IF(AH7='Yearly Info'!$C4, 8, IF(AH7='Yearly Info'!$C5, 8, IF(AH7='Yearly Info'!$C6, 8, IF(AH7='Yearly Info'!$C7, 8, IF(AH7='Yearly Info'!$C8, 8, IF(AH7='Yearly Info'!$C9, 8, IF(AH7='Yearly Info'!$C10, 8, IF(AH7='Yearly Info'!$C11,8,0))))))))))) -> 0 | AI43: =SUM(B43:AH43) -> 16
B44: Leave - Personal | AI44: =IF(SUM(B48:AH48)-AI42-AI43>0,SUM(B48:AH48)-AI42-AI43,0) -> 0
B45: Extended Work Week (Extra Hours) | AI45: =IF(SUM(B48:AH48)-AI42-AI43<0,(SUM(B48:AH48)-AI42-AI43)*-1,0) -> 7.5
A46: Daily Total | B46: =SUM(B45,B43,B42) -> 0 | C46: =SUM(C45,C43,C42) -> 0 | D46: =SUM(D45,D43,D42) -> 0 | E46: =SUM(E45,E43,E42) -> 8 | F46: =SUM(F45,F43,F42) -> 6 | G46: =SUM(G45,G43,G42) -> 0 | H46: =SUM(H45,H43,H42) -> 0 | I46: =SUM(I45,I43,I42) -> 10 | ... AH46: =SUM(AH45,AH43,AH42) -> 4.5 | AI46: =SUM(B46:AH46) -> 183.5
A47: Weekly Total | B47: =IF(B8="Sun",SUM(B46),"") | C47: =IF(C8="Sun",SUM(B46,C46),"") | D47: =IF(D8="Sun",SUM(B46,C46,D46),"") | E47: =IF(E8="Sun",SUM(B46,C46,D46,E46),"") | F47: =SUM(B46:H46) -> 14 | I47: =IF(I8="Sun",SUM(C46,D46,E46,F46,G46,H46,I46),"") | J47: =IF(J8="Sun",SUM(D46,E46,F46,G46,H46,I46,J46),"") | K47: =IF(K8="Sun",SUM(E46,F46,G46,H46,I46,J46,K46),"") | L47: =IF(L8="Sun",SUM(F46,G46,H46,I46,J46,K46,L46),"") | M47: =SUM(I46:O46) -> 50 | P47: =IF(P8="Sun",SUM(J46,K46,L46,M46,N46,O46,P46),"") | Q47: =IF(Q8="Sun",SUM(K46,L46,M46,N46,O46,P46,Q46),"") | R47: =IF(R8="Sun",SUM(L46,M46,N46,O46,P46,Q46,R46),"") | S47: =IF(S8="Sun",SUM(M46,N46,O46,P46,Q46,R46,S46),"") | T47: =SUM(P46:V46) -> 40 | W47: =IF(W8="Sun",SUM(Q46,R46,S46,T46,U46,V46,W46),"") | X47: =IF(X8="Sun",SUM(R46,S46,T46,U46,V46,W46,X46),"") | Y47: =IF(Y8="Sun",SUM(S46,T46,U46,V46,W46,X46,Y46),"") | Z47: =IF(Z8="Sun",SUM(T46,U46,V46,W46,X46,Y46,Z46),"") | AA47: =SUM(W46:AC46) -> 43 | AD47: =IF(AD8="Sun",SUM(X46,Y46,Z46,AA46,AB46,AC46,AD46),"") | AE47: =IF(AE8="Sun",SUM(Y46,Z46,AA46,AB46,AC46,AD46,AE46),"") | AF47: =IF(AF8="Sun",SUM(Z46,AA46,AB46,AC46,AD46,AE46,AF46),"") | AG47: =IF(AG8="Sun",SUM(AA46,AB46,AC46,AD46,AE46,AF46,AG46),"") | AH47: =SUM(AD46:AH46) -> 36.5 | AI47: =SUM(B47:AH47) -> 183.5
B48: =IF(B7>=$D$4,IF(B7<=EOMONTH($D$4,0), IF(B8="S",0,IF(B8="S",0,8)),0),0) -> 0 | C48: =IF(C7>=$D$4,IF(C7<=EOMONTH($D$4,0), IF(C8="S",0,IF(C8="S",0,8)),0),0) -> 0 | D48: =IF(D7>=$D$4,IF(D7<=EOMONTH($D$4,0), IF(D8="S",0,IF(D8="S",0,8)),0),0) -> 0 | E48: =IF(E7>=$D$4,IF(E7<=EOMONTH($D$4,0), IF(E8="S",0,IF(E8="S",0,8)),0),0) -> 8 | F48: =IF(F7>=$D$4,IF(F7<=EOMONTH($D$4,0), IF(F8="S",0,IF(F8="S",0,8)),0),0) -> 8 | G48: =IF(G7>=$D$4,IF(G7<=EOMONTH($D$4,0), IF(G8="S",0,IF(G8="S",0,8)),0),0) -> 0 | H48: =IF(H7>=$D$4,IF(H7<=EOMONTH($D$4,0), IF(H8="S",0,IF(H8="S",0,8)),0),0) -> 0 | I48: =IF(I7>=$D$4,IF(I7<=EOMONTH($D$4,0), IF(I8="S",0,IF(I8="S",0,8)),0),0) -> 8 | ... AH48: =IF(AH7>=$D$4,IF(AH7<=EOMONTH($D$4,0), IF(AH8="S",0,IF(AH8="S",0,8)),0),0) -> 8 | AI48: =SUM(B48:AH48) -> 176
B53: MONTHLY TIME RECORD
B54: Name: | D54: =D3 -> Don Woods
B55: Month: | D55: =D4 -> 46023 | J55: Year: | L55: =L4 -> 2026
...

Sheet JAN-DESC
B2: Name: | D2: ='Yearly Info'!A45 -> Don Woods | E2: =INDIRECT("'" & $Q$1 & "'!D11") -> #REF! | F2: =INDIRECT("'" & $Q$1 & "'!D11") -> #REF! | G2: =INDIRECT("'" & $Q$1 & "'!D11") -> #REF! | H2: =INDIRECT("'" & $Q$1 & "'!D11") -> #REF! | I2: =INDIRECT("'" & $Q$1 & "'!D11") -> #REF! | J2: =INDIRECT("'" & $Q$1 & "'!D11") -> #REF! | K2: =INDIRECT("'" & $Q$1 & "'!D11") -> #REF! | L2: =INDIRECT("'" & $Q$1 & "'!D11") -> #REF! | ... N2: =INDIRECT("'" & $Q$1 & "'!D11") -> #REF!
B3: Month: | D3: ='Yearly Info'!D1 -> 46023 | E3: =INDIRECT("'" & LEFT(UPPER(MID(CELL("filename"),(FIND("]",CELL("filename"))+1),50)),3) & "'!$D$4") -> 46204 | F3: =INDIRECT("'" & LEFT(UPPER(MID(CELL("filename"),(FIND("]",CELL("filename"))+1),50)),3) & "'!$D$4") -> 46204 | G3: =INDIRECT("'" & LEFT(UPPER(MID(CELL("filename"),(FIND("]",CELL("filename"))+1),50)),3) & "'!$D$4") -> 46204 | H3: =INDIRECT("'" & LEFT(UPPER(MID(CELL("filename"),(FIND("]",CELL("filename"))+1),50)),3) & "'!$D$4") -> 46204 | I3: Year: | K3: ='Yearly Info'!B1 -> 2026
A5: Project | B5: Date / Hours | E5: Description
A8: =IF(MONTH(C8)=MONTH(D$3),RIGHT('Yearly Info'!A$14,LEN('Yearly Info'!A$14)-4),"") | B8: =TEXT(C8,"dddd") -> Monday | C8: =INDIRECT("'" & UPPER(LEFT(TEXT($D$3,"mmmm"),3)) & "'!B7") -> 46020 | D8: =INDIRECT("'" & UPPER(LEFT(TEXT($D$3,"mmmm"),3)) & "'!B11") -> 0
A9: =IF(MONTH(C9)=MONTH(D$3),RIGHT('Yearly Info'!A$15,LEN('Yearly Info'!A$15)-4),"") | C9: =C8 -> 46020 | D9: =INDIRECT("'" & UPPER(LEFT(TEXT($D$3,"mmmm"),3)) & "'!B12") -> 0
A10: =IF(MONTH(C10)=MONTH(D$3),RIGHT('Yearly Info'!A$16,LEN('Yearly Info'!A$16)-4),"") | C10: =C9 -> 46020 | D10: =INDIRECT("'" & UPPER(LEFT(TEXT($D$3,"mmmm"),3)) & "'!B13") -> 0
A11: =IF(MONTH(C11)=MONTH(D$3),RIGHT('Yearly Info'!A$17,LEN('Yearly Info'!A$17)-4),"") | C11: =C10 -> 46020 | D11: =INDIRECT("'" & UPPER(LEFT(TEXT($D$3,"mmmm"),3)) & "'!B14") -> 0
A12: =IF(MONTH(C12)=MONTH(D$3),RIGHT('Yearly Info'!A$18,LEN('Yearly Info'!A$18)-4),"") | C12: =C11 -> 46020 | D12: =INDIRECT("'" & UPPER(LEFT(TEXT($D$3,"mmmm"),3)) & "'!B15") -> 0
A13: =IF(MONTH(C13)=MONTH(D$3),RIGHT('Yearly Info'!A$19,LEN('Yearly Info'!A$19)-4),"") | C13: =C12 -> 46020 | D13: =INDIRECT("'" & UPPER(LEFT(TEXT($D$3,"mmmm"),3)) & "'!B16") -> 0
A14: =IF(MONTH(C14)=MONTH(D$3),RIGHT('Yearly Info'!A$20,LEN('Yearly Info'!A$20)-4),"") | C14: =C13 -> 46020 | D14: =INDIRECT("'" & UPPER(LEFT(TEXT($D$3,"mmmm"),3)) & "'!B17") -> 0
A15: =IF(MONTH(C15)=MONTH(D$3),RIGHT('Yearly Info'!A$21,LEN('Yearly Info'!A$21)-4),"") | C15: =C14 -> 46020 | D15: =INDIRECT("'" & UPPER(LEFT(TEXT($D$3,"mmmm"),3)) & "'!B18") -> 0
A16: =IF(MONTH(C16)=MONTH(D$3),RIGHT('Yearly Info'!A$22,LEN('Yearly Info'!A$22)-4),"") | C16: =C15 -> 46020 | D16: =INDIRECT("'" & UPPER(LEFT(TEXT($D$3,"mmmm"),3)) & "'!B19") -> 0
A17: =IF(MONTH(C17)=MONTH(D$3),RIGHT('Yearly Info'!A$23,LEN('Yearly Info'!A$23)-4),"") | C17: =C16 -> 46020 | D17: =INDIRECT("'" & UPPER(LEFT(TEXT($D$3,"mmmm"),3)) & "'!B20") -> 0
A18: =IF(MONTH(C18)=MONTH(D$3),RIGHT('Yearly Info'!A$24,LEN('Yearly Info'!A$24)-4),"") | C18: =C17 -> 46020 | D18: =INDIRECT("'" & UPPER(LEFT(TEXT($D$3,"mmmm"),3)) & "'!B21") -> 0
A19: =IF(MONTH(C19)=MONTH(D$3),RIGHT('Yearly Info'!A$25,LEN('Yearly Info'!A$25)-4),"") | C19: =C18 -> 46020 | D19: =INDIRECT("'" & UPPER(LEFT(TEXT($D$3,"mmmm"),3)) & "'!B22") -> 0
A20: =IF(MONTH(C20)=MONTH(D$3),RIGHT('Yearly Info'!A$26,LEN('Yearly Info'!A$26)-4),"") | C20: =C19 -> 46020 | D20: =INDIRECT("'" & UPPER(LEFT(TEXT($D$3,"mmmm"),3)) & "'!B23") -> 0
A21: =IF(MONTH(C21)=MONTH(D$3),RIGHT('Yearly Info'!A$27,LEN('Yearly Info'!A$27)-4),"") | C21: =C20 -> 46020 | D21: =INDIRECT("'" & UPPER(LEFT(TEXT($D$3,"mmmm"),3)) & "'!B24") -> 0
A22: =IF(MONTH(C22)=MONTH(D$3),RIGHT('Yearly Info'!A$28,LEN('Yearly Info'!A$28)-4),"") | C22: =C21 -> 46020 | D22: =INDIRECT("'" & UPPER(LEFT(TEXT($D$3,"mmmm"),3)) & "'!B25") -> 0
A23: =IF(MONTH(C23)=MONTH(D$3),RIGHT('Yearly Info'!A$29,LEN('Yearly Info'!A$29)-4),"") | C23: =C22 -> 46020 | D23: =INDIRECT("'" & UPPER(LEFT(TEXT($D$3,"mmmm"),3)) & "'!B26") -> 0
A24: =IF(MONTH(C24)=MONTH(D$3),RIGHT('Yearly Info'!A$30,LEN('Yearly Info'!A$30)-4),"") | C24: =C23 -> 46020 | D24: =INDIRECT("'" & UPPER(LEFT(TEXT($D$3,"mmmm"),3)) & "'!B27") -> 0
A25: =IF(MONTH(C25)=MONTH(D$3),RIGHT('Yearly Info'!A$31,LEN('Yearly Info'!A$31)-4),"") | C25: =C24 -> 46020 | D25: =INDIRECT("'" & UPPER(LEFT(TEXT($D$3,"mmmm"),3)) & "'!B28") -> 0
A26: =IF(MONTH(C26)=MONTH(D$3),RIGHT('Yearly Info'!A$32,LEN('Yearly Info'!A$32)-4),"") | C26: =C25 -> 46020 | D26: =INDIRECT("'" & UPPER(LEFT(TEXT($D$3,"mmmm"),3)) & "'!B29") -> 0
A27: =IF(MONTH(C27)=MONTH(D$3),RIGHT('Yearly Info'!A$33,LEN('Yearly Info'!A$33)-4),"") | C27: =C26 -> 46020 | D27: =INDIRECT("'" & UPPER(LEFT(TEXT($D$3,"mmmm"),3)) & "'!B30") -> 0
A28: =IF(MONTH(C28)=MONTH(D$3),RIGHT('Yearly Info'!A$34,LEN('Yearly Info'!A$34)-4),"") | C28: =C27 -> 46020 | D28: =INDIRECT("'" & UPPER(LEFT(TEXT($D$3,"mmmm"),3)) & "'!B31") -> 0
A29: =IF(MONTH(C29)=MONTH(D$3),RIGHT('Yearly Info'!A$35,LEN('Yearly Info'!A$35)-4),"") | C29: =C28 -> 46020 | D29: =INDIRECT("'" & UPPER(LEFT(TEXT($D$3,"mmmm"),3)) & "'!B32") -> 0
A30: =IF(MONTH(C30)=MONTH(D$3),RIGHT('Yearly Info'!A$36,LEN('Yearly Info'!A$36)-4),"") | C30: =C29 -> 46020 | D30: =INDIRECT("'" & UPPER(LEFT(TEXT($D$3,"mmmm"),3)) & "'!B33") -> 0
A31: =IF(MONTH(C31)=MONTH(D$3),RIGHT('Yearly Info'!A$37,LEN('Yearly Info'!A$37)-4),"") | C31: =C30 -> 46020 | D31: =INDIRECT("'" & UPPER(LEFT(TEXT($D$3,"mmmm"),3)) & "'!B34") -> 0
A32: =IF(MONTH(C32)=MONTH(D$3),RIGHT('Yearly Info'!A$38,LEN('Yearly Info'!A$38)-4),"") | C32: =C31 -> 46020 | D32: =INDIRECT("'" & UPPER(LEFT(TEXT($D$3,"mmmm"),3)) & "'!B35") -> 0
A33: =IF(MONTH(C33)=MONTH(D$3),RIGHT('Yearly Info'!A$39,LEN('Yearly Info'!A$39)-4),"") | C33: =C32 -> 46020 | D33: =INDIRECT("'" & UPPER(LEFT(TEXT($D$3,"mmmm"),3)) & "'!B36") -> 0
A34: =IF(MONTH(C34)=MONTH(D$3),RIGHT('Yearly Info'!A$40,LEN('Yearly Info'!A$40)-4),"") | C34: =C33 -> 46020 | D34: =INDIRECT("'" & UPPER(LEFT(TEXT($D$3,"mmmm"),3)) & "'!B37") -> 0
A35: =IF(MONTH(C35)=MONTH(D$3),RIGHT('Yearly Info'!A$41,LEN('Yearly Info'!A$41)-4),"") | C35: =C34 -> 46020 | D35: =INDIRECT("'" & UPPER(LEFT(TEXT($D$3,"mmmm"),3)) & "'!B38") -> 0
A36: =IF(MONTH(C36)=MONTH(D$3),RIGHT('Yearly Info'!A$42,LEN('Yearly Info'!A$42)-4),"") | C36: =C35 -> 46020 | D36: =INDIRECT("'" & UPPER(LEFT(TEXT($D$3,"mmmm"),3)) & "'!B39") -> 0
A37: =IF(MONTH(C37)=MONTH(D$3),RIGHT('Yearly Info'!A$43,LEN('Yearly Info'!A$43)-4),"") | C37: =C36 -> 46020 | D37: =INDIRECT("'" & UPPER(LEFT(TEXT($D$3,"mmmm"),3)) & "'!B40") -> 0
A38: =IF(MONTH(C38)=MONTH(D$3),RIGHT('Yearly Info'!A$14,LEN('Yearly Info'!A$14)-4),"") | B38: =TEXT(C38,"dddd") -> Tuesday | C38: =C8+1 -> 46021 | D38: =INDIRECT("'" & UPPER(TEXT($D$3,"mmm")) & "'!C11") -> 0
A39: =IF(MONTH(C39)=MONTH(D$3),RIGHT('Yearly Info'!A$15,LEN('Yearly Info'!A$15)-4),"") | C39: =C38 -> 46021 | D39: =INDIRECT("'" & UPPER(LEFT(TEXT($D$3,"mmmm"),3)) & "'!C12") -> 0
A40: =IF(MONTH(C40)=MONTH(D$3),RIGHT('Yearly Info'!A$16,LEN('Yearly Info'!A$16)-4),"") | C40: =C39 -> 46021 | D40: =INDIRECT("'" & UPPER(LEFT(TEXT($D$3,"mmmm"),3)) & "'!C13") -> 0
A41: =IF(MONTH(C41)=MONTH(D$3),RIGHT('Yearly Info'!A$17,LEN('Yearly Info'!A$17)-4),"") | C41: =C40 -> 46021 | D41: =INDIRECT("'" & UPPER(LEFT(TEXT($D$3,"mmmm"),3)) & "'!C14") -> 0
A42: =IF(MONTH(C42)=MONTH(D$3),RIGHT('Yearly Info'!A$18,LEN('Yearly Info'!A$18)-4),"") | C42: =C41 -> 46021 | D42: =INDIRECT("'" & UPPER(LEFT(TEXT($D$3,"mmmm"),3)) & "'!C15") -> 0
A43: =IF(MONTH(C43)=MONTH(D$3),RIGHT('Yearly Info'!A$19,LEN('Yearly Info'!A$19)-4),"") | C43: =C42 -> 46021 | D43: =INDIRECT("'" & UPPER(LEFT(TEXT($D$3,"mmmm"),3)) & "'!C16") -> 0
A44: =IF(MONTH(C44)=MONTH(D$3),RIGHT('Yearly Info'!A$20,LEN('Yearly Info'!A$20)-4),"") | C44: =C43 -> 46021 | D44: =INDIRECT("'" & UPPER(LEFT(TEXT($D$3,"mmmm"),3)) & "'!C17") -> 0
...

Sheet FEB
B2: MONTHLY TIME RECORD
B3: Name: | D3: ='Yearly Info'!A45 -> Don Woods
B4: Month: | D4: ='Yearly Info'!D2 -> 46054 | J4: Year: | L4: ='Yearly Info'!B1 -> 2026
A6: Project No. & Description | B6: Day of the Month | AI6: Total Hours
B7: =IF(WEEKDAY(D$4,2)>5,D$4+8 - WEEKDAY(D$4,2),D$4-(WEEKDAY(D$4,2)-1)) -> 46055 | C7: =B7+1 -> 46056 | D7: =C7+1 -> 46057 | E7: =D7+1 -> 46058 | F7: =E7+1 -> 46059 | G7: =F7+1 -> 46060 | H7: =G7+1 -> 46061 | I7: =H7+1 -> 46062 | J7: =I7+1 -> 46063 | ... AH7: =AG7+1 -> 46087 | AI7: Hours
B8: =HYPERLINK("#'"&UPPER(LEFT(TEXT($D$4,"mmmm"),3))&"-DEQ'!E8",TEXT(WEEKDAY(B7),"ddd")) -> Mon | C8: =HYPERLINK("#'"&UPPER(LEFT(TEXT($D$4,"mmmm"),3))&"-DEQ'!E15",TEXT(WEEKDAY(C7),"ddd")) -> Tue | D8: =HYPERLINK("#'"&UPPER(LEFT(TEXT($D$4,"mmmm"),3))&"-DEQ'!E22",TEXT(WEEKDAY(D7),"ddd")) -> Wed | E8: =HYPERLINK("#'"&UPPER(LEFT(TEXT($D$4,"mmmm"),3))&"-DEQ'!E29",TEXT(WEEKDAY(E7),"ddd")) -> Thu | F8: =HYPERLINK("#'"&UPPER(LEFT(TEXT($D$4,"mmmm"),3))&"-DEQ'!E36",TEXT(WEEKDAY(F7),"ddd")) -> Fri | G8: =LEFT(TEXT(WEEKDAY(G7),"ddd"),1) -> S | H8: =LEFT(TEXT(WEEKDAY(H7),"ddd"),1) -> S | I8: =HYPERLINK("#'"&UPPER(LEFT(TEXT($D$4,"mmmm"),3))&"-DEQ'!E43",TEXT(WEEKDAY(I7),"ddd")) -> Mon | J8: =HYPERLINK("#'"&UPPER(LEFT(TEXT($D$4,"mmmm"),3))&"-DEQ'!E50",TEXT(WEEKDAY(J7),"ddd")) -> Tue | K8: =HYPERLINK("#'"&UPPER(LEFT(TEXT($D$4,"mmmm"),3))&"-DEQ'!E57",TEXT(WEEKDAY(K7),"ddd")) -> Wed | L8: =HYPERLINK("#'"&UPPER(LEFT(TEXT($D$4,"mmmm"),3))&"-DEQ'!E64",TEXT(WEEKDAY(L7),"ddd")) -> Thu | M8: =HYPERLINK("#'"&UPPER(LEFT(TEXT($D$4,"mmmm"),3))&"-DEQ'!E71",TEXT(WEEKDAY(M7),"ddd")) -> Fri | N8: =LEFT(TEXT(WEEKDAY(N7),"ddd"),1) -> S | O8: =LEFT(TEXT(WEEKDAY(O7),"ddd"),1) -> S | P8: =HYPERLINK("#'"&UPPER(LEFT(TEXT($D$4,"mmmm"),3))&"-DEQ'!E78",TEXT(WEEKDAY(P7),"ddd")) -> Mon | Q8: =HYPERLINK("#'"&UPPER(LEFT(TEXT($D$4,"mmmm"),3))&"-DEQ'!E85",TEXT(WEEKDAY(Q7),"ddd")) -> Tue | R8: =HYPERLINK("#'"&UPPER(LEFT(TEXT($D$4,"mmmm"),3))&"-DEQ'!E92",TEXT(WEEKDAY(R7),"ddd")) -> Wed | S8: =HYPERLINK("#'"&UPPER(LEFT(TEXT($D$4,"mmmm"),3))&"-DEQ'!E99",TEXT(WEEKDAY(S7),"ddd")) -> Thu | T8: =HYPERLINK("#'"&UPPER(LEFT(TEXT($D$4,"mmmm"),3))&"-DEQ'!E106",TEXT(WEEKDAY(T7),"ddd")) -> Fri | U8: =LEFT(TEXT(WEEKDAY(U7),"ddd"),1) -> S | V8: =LEFT(TEXT(WEEKDAY(V7),"ddd"),1) -> S | W8: =HYPERLINK("#'"&UPPER(LEFT(TEXT($D$4,"mmmm"),3))&"-DEQ'!E113",TEXT(WEEKDAY(W7),"ddd")) -> Mon | X8: =HYPERLINK("#'"&UPPER(LEFT(TEXT($D$4,"mmmm"),3))&"-DEQ'!E120",TEXT(WEEKDAY(X7),"ddd")) -> Tue | Y8: =HYPERLINK("#'"&UPPER(LEFT(TEXT($D$4,"mmmm"),3))&"-DEQ'!E127",TEXT(WEEKDAY(Y7),"ddd")) -> Wed | Z8: =HYPERLINK("#'"&UPPER(LEFT(TEXT($D$4,"mmmm"),3))&"-DEQ'!E134",TEXT(WEEKDAY(Z7),"ddd")) -> Thu | AA8: =HYPERLINK("#'"&UPPER(LEFT(TEXT($D$4,"mmmm"),3))&"-DEQ'!E141",TEXT(WEEKDAY(AA7),"ddd")) -> Fri | AB8: =LEFT(TEXT(WEEKDAY(AB7),"ddd"),1) -> S | AC8: =LEFT(TEXT(WEEKDAY(AC7),"ddd"),1) -> S | AD8: =HYPERLINK("#'"&UPPER(LEFT(TEXT($D$4,"mmmm"),3))&"-DEQ'!E149",TEXT(WEEKDAY(AD7),"ddd")) -> Mon | AE8: =HYPERLINK("#'"&UPPER(LEFT(TEXT($D$4,"mmmm"),3))&"-DEQ'!E155",TEXT(WEEKDAY(AE7),"ddd")) -> Tue | AF8: =HYPERLINK("#'"&UPPER(LEFT(TEXT($D$4,"mmmm"),3))&"-DEQ'!E162",TEXT(WEEKDAY(AF7),"ddd")) -> Wed | AG8: =HYPERLINK("#'"&UPPER(LEFT(TEXT($D$4,"mmmm"),3))&"-DEQ'!E169",TEXT(WEEKDAY(AG7),"ddd")) -> Thu | AH8: =HYPERLINK("#'"&UPPER(LEFT(TEXT($D$4,"mmmm"),3))&"-DEQ'!E176",TEXT(WEEKDAY(AH7),"ddd")) -> Fri
A9: Hours
A10: ='Yearly Info'!A13 -> Enter Job #s on Yearly Info Tab
A11: ='Yearly Info'!A14 -> RICS Support for MDEQ | B11: 7 | C11: 5 | D11: 7 | E11: 5 | F11: 3 | L11: 3 | S11: 3 | T11: 8 | W11: 4 | Y11: 4 | Z11: 6 | AA11: 2 | AI11: =SUM(B11:AH11) -> 57
A12: ='Yearly Info'!A15 -> MDEQ | AI12: =SUM(B12:AH12) -> 0
A13: ='Yearly Info'!A16 -> RICS Idea Portal | AI13: =SUM(B13:AH13) -> 0
A14: ='Yearly Info'!A17 -> MSWIS | C14: 4 | D14: 1 | E14: 3 | F14: 4 | I14: 8 | J14: 8 | K14: 8 | L14: 5 | M14: 8 | Q14: 10 | R14: 6 | S14: 5 | W14: 2 | X14: 2 | AA14: 1 | AI14: =SUM(B14:AH14) -> 75
A15: ='Yearly Info'!A18 -> GeoSpatial | AI15: =SUM(B15:AH15) -> 0
A16: ='Yearly Info'!A19 -> RICS Dashboard | W16: 1 | AI16: =SUM(B16:AH16) -> 1
A17: ='Yearly Info'!A20 -> MDWFP NRIS | F17: 1 | R17: 3 | X17: 1 | AI17: =SUM(B17:AH17) -> 5
A18: ='Yearly Info'!A21 -> MSWIS MRVA 4 CLOSED | X18: 5 | Z18: 4 | AA18: 3 | AI18: =SUM(B18:AH18) -> 12
A19: ='Yearly Info'!A22 -> Tackett | W19: 1 | Y19: 4 | AI19: =SUM(B19:AH19) -> 5
A20: ='Yearly Info'!A23 -> 0 | AI20: =SUM(B20:AH20) -> 0
A21: ='Yearly Info'!A24 -> 0 | AI21: =SUM(B21:AH21) -> 0
A22: ='Yearly Info'!A25 -> 0 | AI22: =SUM(B22:AH22) -> 0
A23: ='Yearly Info'!A26 -> 0 | AI23: =SUM(B23:AH23) -> 0
A24: ='Yearly Info'!A27 -> 0 | AI24: =SUM(B24:AH24) -> 0
A25: ='Yearly Info'!A28 -> 0 | AI25: =SUM(B25:AH25) -> 0
A26: ='Yearly Info'!A29 -> 0 | AI26: =SUM(B26:AH26) -> 0
A27: ='Yearly Info'!A30 -> 0 | AI27: =SUM(B27:AH27) -> 0
A28: ='Yearly Info'!A31 -> 0 | AI28: =SUM(B28:AH28) -> 0
A29: ='Yearly Info'!A32 -> 0 | AI29: =SUM(B29:AH29) -> 0
A30: ='Yearly Info'!A33 -> 0 | AI30: =SUM(B30:AH30) -> 0
A31: ='Yearly Info'!A34 -> 0 | AI31: =SUM(B31:AH31) -> 0
... A40: ='Yearly Info'!A43 | AI40: =SUM(B40:AH40) -> 0
AI41: =SUM(B41:AH41) -> 0
A42: Total | B42: =SUM(B9:B40) -> 7 | C42: =SUM(C9:C40) -> 9 | D42: =SUM(D9:D40) -> 8 | E42: =SUM(E9:E40) -> 8 | F42: =SUM(F9:F40) -> 8 | G42: =SUM(G9:G40) -> 0 | H42: =SUM(H9:H40) -> 0 | I42: =SUM(I9:I40) -> 8 | ... AE42: =SUM(AE9:AE40) -> 0 | AF42: =SUM(AF9:AF41) -> 0 | AG42: =SUM(AG9:AG40) -> 0 | AH42: =SUM(AH9:AH40) -> 0 | AI42: =SUM(AI11:AI41) -> 155
A43: Leave - Holiday | B43: =IF(B7<$D$4,0, IF(B7='Yearly Info'!$C2, 8, IF(B7='Yearly Info'!$C3, 8, IF(B7='Yearly Info'!$C4, 8, IF(B7='Yearly Info'!$C5, 8, IF(B7='Yearly Info'!$C6, 8, IF(B7='Yearly Info'!$C7, 8, IF(B7='Yearly Info'!$C8, 8, IF(B7='Yearly Info'!$C9, 8, IF(B7='Yearly Info'!$C10, 8, IF(B7='Yearly Info'!$C11,8,0))))))))))) -> 0 | C43: =IF(C7<$D$4,0, IF(C7='Yearly Info'!$C2, 8, IF(C7='Yearly Info'!$C3, 8, IF(C7='Yearly Info'!$C4, 8, IF(C7='Yearly Info'!$C5, 8, IF(C7='Yearly Info'!$C6, 8, IF(C7='Yearly Info'!$C7, 8, IF(C7='Yearly Info'!$C8, 8, IF(C7='Yearly Info'!$C9, 8, IF(C7='Yearly Info'!$C10, 8, IF(C7='Yearly Info'!$C11,8,0))))))))))) -> 0 | D43: =IF(D7<$D$4,0, IF(D7='Yearly Info'!$C2, 8, IF(D7='Yearly Info'!$C3, 8, IF(D7='Yearly Info'!$C4, 8, IF(D7='Yearly Info'!$C5, 8, IF(D7='Yearly Info'!$C6, 8, IF(D7='Yearly Info'!$C7, 8, IF(D7='Yearly Info'!$C8, 8, IF(D7='Yearly Info'!$C9, 8, IF(D7='Yearly Info'!$C10, 8, IF(D7='Yearly Info'!$C11,8,0))))))))))) -> 0 | E43: =IF(E7<$D$4,0, IF(E7='Yearly Info'!$C2, 8, IF(E7='Yearly Info'!$C3, 8, IF(E7='Yearly Info'!$C4, 8, IF(E7='Yearly Info'!$C5, 8, IF(E7='Yearly Info'!$C6, 8, IF(E7='Yearly Info'!$C7, 8, IF(E7='Yearly Info'!$C8, 8, IF(E7='Yearly Info'!$C9, 8, IF(E7='Yearly Info'!$C10, 8, IF(E7='Yearly Info'!$C11,8,0))))))))))) -> 0 | F43: =IF(F7<$D$4,0, IF(F7='Yearly Info'!$C2, 8, IF(F7='Yearly Info'!$C3, 8, IF(F7='Yearly Info'!$C4, 8, IF(F7='Yearly Info'!$C5, 8, IF(F7='Yearly Info'!$C6, 8, IF(F7='Yearly Info'!$C7, 8, IF(F7='Yearly Info'!$C8, 8, IF(F7='Yearly Info'!$C9, 8, IF(F7='Yearly Info'!$C10, 8, IF(F7='Yearly Info'!$C11,8,0))))))))))) -> 0 | G43: =IF(G7='Yearly Info'!$C2, 8, IF(G7='Yearly Info'!$C3, 8, IF(G7='Yearly Info'!$C4, 8, IF(G7='Yearly Info'!$C5, 8, IF(G7='Yearly Info'!$C6, 8, IF(G7='Yearly Info'!$C7, 8, IF(G7='Yearly Info'!$C8, 8, IF(G7='Yearly Info'!$C9, 8, IF(G7='Yearly Info'!$C10, 8, IF(G7='Yearly Info'!$C11,8,0)))))))))) -> 0 | H43: =IF(H7='Yearly Info'!$C2, 8, IF(H7='Yearly Info'!$C3, 8, IF(H7='Yearly Info'!$C4, 8, IF(H7='Yearly Info'!$C5, 8, IF(H7='Yearly Info'!$C6, 8, IF(H7='Yearly Info'!$C7, 8, IF(H7='Yearly Info'!$C8, 8, IF(H7='Yearly Info'!$C9, 8, IF(H7='Yearly Info'!$C10, 8, IF(H7='Yearly Info'!$C11,8,0)))))))))) -> 0 | I43: =IF(I7='Yearly Info'!$C2, 8, IF(I7='Yearly Info'!$C3, 8, IF(I7='Yearly Info'!$C4, 8, IF(I7='Yearly Info'!$C5, 8, IF(I7='Yearly Info'!$C6, 8, IF(I7='Yearly Info'!$C7, 8, IF(I7='Yearly Info'!$C8, 8, IF(I7='Yearly Info'!$C9, 8, IF(I7='Yearly Info'!$C10, 8, IF(I7='Yearly Info'!$C11,8,0)))))))))) -> 0 | J43: =IF(J7='Yearly Info'!$C2, 8, IF(J7='Yearly Info'!$C3, 8, IF(J7='Yearly Info'!$C4, 8, IF(J7='Yearly Info'!$C5, 8, IF(J7='Yearly Info'!$C6, 8, IF(J7='Yearly Info'!$C7, 8, IF(J7='Yearly Info'!$C8, 8, IF(J7='Yearly Info'!$C9, 8, IF(J7='Yearly Info'!$C10, 8, IF(J7='Yearly Info'!$C11,8,0)))))))))) -> 0 | K43: =IF(K7='Yearly Info'!$C2, 8, IF(K7='Yearly Info'!$C3, 8, IF(K7='Yearly Info'!$C4, 8, IF(K7='Yearly Info'!$C5, 8, IF(K7='Yearly Info'!$C6, 8, IF(K7='Yearly Info'!$C7, 8, IF(K7='Yearly Info'!$C8, 8, IF(K7='Yearly Info'!$C9, 8, IF(K7='Yearly Info'!$C10, 8, IF(K7='Yearly Info'!$C11,8,0)))))))))) -> 0 | L43: =IF(L7='Yearly Info'!$C2, 8, IF(L7='Yearly Info'!$C3, 8, IF(L7='Yearly Info'!$C4, 8, IF(L7='Yearly Info'!$C5, 8, IF(L7='Yearly Info'!$C6, 8, IF(L7='Yearly Info'!$C7, 8, IF(L7='Yearly Info'!$C8, 8, IF(L7='Yearly Info'!$C9, 8, IF(L7='Yearly Info'!$C10, 8, IF(L7='Yearly Info'!$C11,8,0)))))))))) -> 0 | M43: =IF(M7='Yearly Info'!$C2, 8, IF(M7='Yearly Info'!$C3, 8, IF(M7='Yearly Info'!$C4, 8, IF(M7='Yearly Info'!$C5, 8, IF(M7='Yearly Info'!$C6, 8, IF(M7='Yearly Info'!$C7, 8, IF(M7='Yearly Info'!$C8, 8, IF(M7='Yearly Info'!$C9, 8, IF(M7='Yearly Info'!$C10, 8, IF(M7='Yearly Info'!$C11,8,0)))))))))) -> 0 | N43: =IF(N7='Yearly Info'!$C2, 8, IF(N7='Yearly Info'!$C3, 8, IF(N7='Yearly Info'!$C4, 8, IF(N7='Yearly Info'!$C5, 8, IF(N7='Yearly Info'!$C6, 8, IF(N7='Yearly Info'!$C7, 8, IF(N7='Yearly Info'!$C8, 8, IF(N7='Yearly Info'!$C9, 8, IF(N7='Yearly Info'!$C10, 8, IF(N7='Yearly Info'!$C11,8,0)))))))))) -> 0 | ... AA43: =IF(AA7='Yearly Info'!$C2, 8, IF(AA7='Yearly Info'!$C3, 8, IF(AA7='Yearly Info'!$C4, 8, IF(AA7='Yearly Info'!$C5, 8, IF(AA7='Yearly Info'!$C6, 8, IF(AA7='Yearly Info'!$C7, 8, IF(AA7='Yearly Info'!$C8, 8, IF(AA7='Yearly Info'!$C9, 8, IF(AA7='Yearly Info'!$C10, 8, IF(AA7='Yearly Info'!$C11,8,0)))))))))) -> 0 | AB43: =IF(AB7>EOMONTH($D$4,0),0, IF(AB7='Yearly Info'!$C2, 8, IF(AB7='Yearly Info'!$C3, 8, IF(AB7='Yearly Info'!$C4, 8, IF(AB7='Yearly Info'!$C5, 8, IF(AB7='Yearly Info'!$C6, 8, IF(AB7='Yearly Info'!$C7, 8, IF(AB7='Yearly Info'!$C8, 8, IF(AB7='Yearly Info'!$C9, 8, IF(AB7='Yearly Info'!$C10, 8, IF(AB7='Yearly Info'!$C11,8,0))))))))))) -> 0 | AC43: =IF(AC7>EOMONTH($D$4,0),0, IF(AC7='Yearly Info'!$C2, 8, IF(AC7='Yearly Info'!$C3, 8, IF(AC7='Yearly Info'!$C4, 8, IF(AC7='Yearly Info'!$C5, 8, IF(AC7='Yearly Info'!$C6, 8, IF(AC7='Yearly Info'!$C7, 8, IF(AC7='Yearly Info'!$C8, 8, IF(AC7='Yearly Info'!$C9, 8, IF(AC7='Yearly Info'!$C10, 8, IF(AC7='Yearly Info'!$C11,8,0))))))))))) -> 0 | AE43: =IF(AE7>EOMONTH($D$4,0),0, IF(AE7='Yearly Info'!$C2, 8, IF(AE7='Yearly Info'!$C3, 8, IF(AE7='Yearly Info'!$C4, 8, IF(AE7='Yearly Info'!$C5, 8, IF(AE7='Yearly Info'!$C6, 8, IF(AE7='Yearly Info'!$C7, 8, IF(AE7='Yearly Info'!$C8, 8, IF(AE7='Yearly Info'!$C9, 8, IF(AE7='Yearly Info'!$C10, 8, IF(AE7='Yearly Info'!$C11,8,0))))))))))) -> 0 | AF43: =IF(AF7>EOMONTH($D$4,0),0, IF(AF7='Yearly Info'!$C2, 8, IF(AF7='Yearly Info'!$C3, 8, IF(AF7='Yearly Info'!$C4, 8, IF(AF7='Yearly Info'!$C5, 8, IF(AF7='Yearly Info'!$C6, 8, IF(AF7='Yearly Info'!$C7, 8, IF(AF7='Yearly Info'!$C8, 8, IF(AF7='Yearly Info'!$C9, 8, IF(AF7='Yearly Info'!$C10, 8, IF(AF7='Yearly Info'!$C11,8,0))))))))))) -> 0 | AG43: =IF(AG7>EOMONTH($D$4,0),0, IF(AG7='Yearly Info'!$C2, 8, IF(AG7='Yearly Info'!$C3, 8, IF(AG7='Yearly Info'!$C4, 8, IF(AG7='Yearly Info'!$C5, 8, IF(AG7='Yearly Info'!$C6, 8, IF(AG7='Yearly Info'!$C7, 8, IF(AG7='Yearly Info'!$C8, 8, IF(AG7='Yearly Info'!$C9, 8, IF(AG7='Yearly Info'!$C10, 8, IF(AG7='Yearly Info'!$C11,8,0))))))))))) -> 0 | AH43: =IF(AH7>EOMONTH($D$4,0),0, IF(AH7='Yearly Info'!$C2, 8, IF(AH7='Yearly Info'!$C3, 8, IF(AH7='Yearly Info'!$C4, 8, IF(AH7='Yearly Info'!$C5, 8, IF(AH7='Yearly Info'!$C6, 8, IF(AH7='Yearly Info'!$C7, 8, IF(AH7='Yearly Info'!$C8, 8, IF(AH7='Yearly Info'!$C9, 8, IF(AH7='Yearly Info'!$C10, 8, IF(AH7='Yearly Info'!$C11,8,0))))))))))) -> 0 | AI43: =SUM(B43:AH43) -> 8
B44: Leave - Personal | AI44: =IF(SUM(B48:AH48)-AI42-AI43>0,SUM(B48:AH48)-AI42-AI43,0) -> 0
B45: Extended Work Week (Extra Hours) | AI45: =IF(SUM(B48:AH48)-AI42-AI43<0,(SUM(B48:AH48)-AI42-AI43)*-1,0) -> 3
A46: Daily Total | B46: =SUM(B45,B43,B42) -> 7 | C46: =SUM(C45,C43,C42) -> 9 | D46: =SUM(D45,D43,D42) -> 8 | E46: =SUM(E45,E43,E42) -> 8 | F46: =SUM(F45,F43,F42) -> 8 | G46: =SUM(G45,G43,G42) -> 0 | H46: =SUM(H45,H43,H42) -> 0 | I46: =SUM(I45,I43,I42) -> 8 | ... AH46: =SUM(AH45,AH43,AH42) -> 0 | AI46: =SUM(B46:AH46) -> 163
A47: Weekly Total | B47: =IF(B8="Sun",SUM(B46),"") | C47: =IF(C8="Sun",SUM(B46,C46),"") | D47: =IF(D8="Sun",SUM(B46,C46,D46),"") | E47: =IF(E8="Sun",SUM(B46,C46,D46,E46),"") | F47: =SUM(B46:H46) -> 40 | I47: =IF(I8="Sun",SUM(C46,D46,E46,F46,G46,H46,I46),"") | J47: =IF(J8="Sun",SUM(D46,E46,F46,G46,H46,I46,J46),"") | K47: =IF(K8="Sun",SUM(E46,F46,G46,H46,I46,J46,K46),"") | L47: =IF(L8="Sun",SUM(F46,G46,H46,I46,J46,K46,L46),"") | M47: =SUM(I46:O46) -> 40 | P47: =IF(P8="Sun",SUM(J46,K46,L46,M46,N46,O46,P46),"") | Q47: =IF(Q8="Sun",SUM(K46,L46,M46,N46,O46,P46,Q46),"") | R47: =IF(R8="Sun",SUM(L46,M46,N46,O46,P46,Q46,R46),"") | S47: =IF(S8="Sun",SUM(M46,N46,O46,P46,Q46,R46,S46),"") | T47: =SUM(P46:V46) -> 43 | W47: =IF(W8="Sun",SUM(Q46,R46,S46,T46,U46,V46,W46),"") | X47: =IF(X8="Sun",SUM(R46,S46,T46,U46,V46,W46,X46),"") | Y47: =IF(Y8="Sun",SUM(S46,T46,U46,V46,W46,X46,Y46),"") | Z47: =IF(Z8="Sun",SUM(T46,U46,V46,W46,X46,Y46,Z46),"") | AA47: =SUM(W46:AC46) -> 40 | AD47: =IF(AD8="Sun",SUM(X46,Y46,Z46,AA46,AB46,AC46,AD46),"") | AE47: =IF(AE8="Sun",SUM(Y46,Z46,AA46,AB46,AC46,AD46,AE46),"") | AF47: =IF(AF8="Sun",SUM(Z46,AA46,AB46,AC46,AD46,AE46,AF46),"") | AG47: =IF(AG8="Sun",SUM(AA46,AB46,AC46,AD46,AE46,AF46,AG46),"") | AH47: =SUM(AD46:AH46) -> 0 | AI47: =SUM(B47:AH47) -> 163
B48: =IF(B7>=$D$4,IF(B7<=EOMONTH($D$4,0), IF(B8="S",0,IF(B8="S",0,8)),0),0) -> 8 | C48: =IF(C7>=$D$4,IF(C7<=EOMONTH($D$4,0), IF(C8="S",0,IF(C8="S",0,8)),0),0) -> 8 | D48: =IF(D7>=$D$4,IF(D7<=EOMONTH($D$4,0), IF(D8="S",0,IF(D8="S",0,8)),0),0) -> 8 | E48: =IF(E7>=$D$4,IF(E7<=EOMONTH($D$4,0), IF(E8="S",0,IF(E8="S",0,8)),0),0) -> 8 | F48: =IF(F7>=$D$4,IF(F7<=EOMONTH($D$4,0), IF(F8="S",0,IF(F8="S",0,8)),0),0) -> 8 | G48: =IF(G7>=$D$4,IF(G7<=EOMONTH($D$4,0), IF(G8="S",0,IF(G8="S",0,8)),0),0) -> 0 | H48: =IF(H7>=$D$4,IF(H7<=EOMONTH($D$4,0), IF(H8="S",0,IF(H8="S",0,8)),0),0) -> 0 | I48: =IF(I7>=$D$4,IF(I7<=EOMONTH($D$4,0), IF(I8="S",0,IF(I8="S",0,8)),0),0) -> 8 | ... AH48: =IF(AH7>=$D$4,IF(AH7<=EOMONTH($D$4,0), IF(AH8="S",0,IF(AH8="S",0,8)),0),0) -> 0 | AI48: =SUM(B48:AH48) -> 160
B53: MONTHLY TIME RECORD
B54: Name: | D54: =D3 -> Don Woods
...

Sheet FEB-DESC
B2: Name: | D2: ='Yearly Info'!A45 -> Don Woods | E2: =INDIRECT("'" & $Q$1 & "'!D11") -> #REF! | F2: =INDIRECT("'" & $Q$1 & "'!D11") -> #REF! | G2: =INDIRECT("'" & $Q$1 & "'!D11") -> #REF! | H2: =INDIRECT("'" & $Q$1 & "'!D11") -> #REF! | I2: =INDIRECT("'" & $Q$1 & "'!D11") -> #REF! | J2: =INDIRECT("'" & $Q$1 & "'!D11") -> #REF! | K2: =INDIRECT("'" & $Q$1 & "'!D11") -> #REF! | L2: =INDIRECT("'" & $Q$1 & "'!D11") -> #REF! | ... N2: =INDIRECT("'" & $Q$1 & "'!D11") -> #REF!
B3: Month: | D3: ='Yearly Info'!D2 -> 46054 | E3: =INDIRECT("'" & LEFT(UPPER(MID(CELL("filename"),(FIND("]",CELL("filename"))+1),50)),3) & "'!$D$4") -> 46204 | F3: =INDIRECT("'" & LEFT(UPPER(MID(CELL("filename"),(FIND("]",CELL("filename"))+1),50)),3) & "'!$D$4") -> 46204 | G3: =INDIRECT("'" & LEFT(UPPER(MID(CELL("filename"),(FIND("]",CELL("filename"))+1),50)),3) & "'!$D$4") -> 46204 | H3: =INDIRECT("'" & LEFT(UPPER(MID(CELL("filename"),(FIND("]",CELL("filename"))+1),50)),3) & "'!$D$4") -> 46204 | I3: Year: | K3: ='Yearly Info'!B1 -> 2026
A5: Project | B5: Date / Hours | E5: Description
A8: =IF(MONTH(C8)=MONTH(D$3),RIGHT('Yearly Info'!A$14,LEN('Yearly Info'!A$14)-4),"") -> RICS Support for MDEQ | B8: =TEXT(C8,"dddd") -> Monday | C8: =INDIRECT("'" & UPPER(LEFT(TEXT($D$3,"mmmm"),3)) & "'!B7") -> 46055 | D8: =INDIRECT("'" & UPPER(LEFT(TEXT($D$3,"mmmm"),3)) & "'!B11") -> 7 | E8: Graph API Migration SharePoint
A9: =IF(MONTH(C9)=MONTH(D$3),RIGHT('Yearly Info'!A$15,LEN('Yearly Info'!A$15)-4),"") -> MDEQ | C9: =C8 -> 46055 | D9: =INDIRECT("'" & UPPER(LEFT(TEXT($D$3,"mmmm"),3)) & "'!B12") -> 0
A10: =IF(MONTH(C10)=MONTH(D$3),RIGHT('Yearly Info'!A$16,LEN('Yearly Info'!A$16)-4),"") -> RICS Idea Portal | C10: =C9 -> 46055 | D10: =INDIRECT("'" & UPPER(LEFT(TEXT($D$3,"mmmm"),3)) & "'!B13") -> 0
A11: =IF(MONTH(C11)=MONTH(D$3),RIGHT('Yearly Info'!A$17,LEN('Yearly Info'!A$17)-4),"") -> MSWIS | C11: =C10 -> 46055 | D11: =INDIRECT("'" & UPPER(LEFT(TEXT($D$3,"mmmm"),3)) & "'!B14") -> 0
A12: =IF(MONTH(C12)=MONTH(D$3),RIGHT('Yearly Info'!A$18,LEN('Yearly Info'!A$18)-4),"") -> GeoSpatial | C12: =C11 -> 46055 | D12: =INDIRECT("'" & UPPER(LEFT(TEXT($D$3,"mmmm"),3)) & "'!B15") -> 0
A13: =IF(MONTH(C13)=MONTH(D$3),RIGHT('Yearly Info'!A$19,LEN('Yearly Info'!A$19)-4),"") -> RICS Dashboard | C13: =C12 -> 46055 | D13: =INDIRECT("'" & UPPER(LEFT(TEXT($D$3,"mmmm"),3)) & "'!B16") -> 0
A14: =IF(MONTH(C14)=MONTH(D$3),RIGHT('Yearly Info'!A$20,LEN('Yearly Info'!A$20)-4),"") -> MDWFP NRIS | C14: =C13 -> 46055 | D14: =INDIRECT("'" & UPPER(LEFT(TEXT($D$3,"mmmm"),3)) & "'!B17") -> 0
A15: =IF(MONTH(C15)=MONTH(D$3),RIGHT('Yearly Info'!A$21,LEN('Yearly Info'!A$21)-4),"") -> MSWIS MRVA 4 CLOSED | C15: =C14 -> 46055 | D15: =INDIRECT("'" & UPPER(LEFT(TEXT($D$3,"mmmm"),3)) & "'!B18") -> 0
A16: =IF(MONTH(C16)=MONTH(D$3),RIGHT('Yearly Info'!A$22,LEN('Yearly Info'!A$22)-4),"") -> Tackett | C16: =C15 -> 46055 | D16: =INDIRECT("'" & UPPER(LEFT(TEXT($D$3,"mmmm"),3)) & "'!B19") -> 0
A17: =IF(MONTH(C17)=MONTH(D$3),RIGHT('Yearly Info'!A$23,LEN('Yearly Info'!A$23)-4),"") -> #VALUE! | C17: =C16 -> 46055 | D17: =INDIRECT("'" & UPPER(LEFT(TEXT($D$3,"mmmm"),3)) & "'!B20") -> 0
A18: =IF(MONTH(C18)=MONTH(D$3),RIGHT('Yearly Info'!A$24,LEN('Yearly Info'!A$24)-4),"") -> #VALUE! | C18: =C17 -> 46055 | D18: =INDIRECT("'" & UPPER(LEFT(TEXT($D$3,"mmmm"),3)) & "'!B21") -> 0
A19: =IF(MONTH(C19)=MONTH(D$3),RIGHT('Yearly Info'!A$25,LEN('Yearly Info'!A$25)-4),"") -> #VALUE! | C19: =C18 -> 46055 | D19: =INDIRECT("'" & UPPER(LEFT(TEXT($D$3,"mmmm"),3)) & "'!B22") -> 0
A20: =IF(MONTH(C20)=MONTH(D$3),RIGHT('Yearly Info'!A$26,LEN('Yearly Info'!A$26)-4),"") -> #VALUE! | C20: =C19 -> 46055 | D20: =INDIRECT("'" & UPPER(LEFT(TEXT($D$3,"mmmm"),3)) & "'!B23") -> 0
A21: =IF(MONTH(C21)=MONTH(D$3),RIGHT('Yearly Info'!A$27,LEN('Yearly Info'!A$27)-4),"") -> #VALUE! | C21: =C20 -> 46055 | D21: =INDIRECT("'" & UPPER(LEFT(TEXT($D$3,"mmmm"),3)) & "'!B24") -> 0
A22: =IF(MONTH(C22)=MONTH(D$3),RIGHT('Yearly Info'!A$28,LEN('Yearly Info'!A$28)-4),"") -> #VALUE! | C22: =C21 -> 46055 | D22: =INDIRECT("'" & UPPER(LEFT(TEXT($D$3,"mmmm"),3)) & "'!B25") -> 0
A23: =IF(MONTH(C23)=MONTH(D$3),RIGHT('Yearly Info'!A$29,LEN('Yearly Info'!A$29)-4),"") -> #VALUE! | C23: =C22 -> 46055 | D23: =INDIRECT("'" & UPPER(LEFT(TEXT($D$3,"mmmm"),3)) & "'!B26") -> 0
A24: =IF(MONTH(C24)=MONTH(D$3),RIGHT('Yearly Info'!A$30,LEN('Yearly Info'!A$30)-4),"") -> #VALUE! | C24: =C23 -> 46055 | D24: =INDIRECT("'" & UPPER(LEFT(TEXT($D$3,"mmmm"),3)) & "'!B27") -> 0
A25: =IF(MONTH(C25)=MONTH(D$3),RIGHT('Yearly Info'!A$31,LEN('Yearly Info'!A$31)-4),"") -> #VALUE! | C25: =C24 -> 46055 | D25: =INDIRECT("'" & UPPER(LEFT(TEXT($D$3,"mmmm"),3)) & "'!B28") -> 0
A26: =IF(MONTH(C26)=MONTH(D$3),RIGHT('Yearly Info'!A$32,LEN('Yearly Info'!A$32)-4),"") -> #VALUE! | C26: =C25 -> 46055 | D26: =INDIRECT("'" & UPPER(LEFT(TEXT($D$3,"mmmm"),3)) & "'!B29") -> 0
A27: =IF(MONTH(C27)=MONTH(D$3),RIGHT('Yearly Info'!A$33,LEN('Yearly Info'!A$33)-4),"") -> #VALUE! | C27: =C26 -> 46055 | D27: =INDIRECT("'" & UPPER(LEFT(TEXT($D$3,"mmmm"),3)) & "'!B30") -> 0
A28: =IF(MONTH(C28)=MONTH(D$3),RIGHT('Yearly Info'!A$34,LEN('Yearly Info'!A$34)-4),"") -> #VALUE! | C28: =C27 -> 46055 | D28: =INDIRECT("'" & UPPER(LEFT(TEXT($D$3,"mmmm"),3)) & "'!B31") -> 0
A29: =IF(MONTH(C29)=MONTH(D$3),RIGHT('Yearly Info'!A$35,LEN('Yearly Info'!A$35)-4),"") -> #VALUE! | C29: =C28 -> 46055 | D29: =INDIRECT("'" & UPPER(LEFT(TEXT($D$3,"mmmm"),3)) & "'!B32") -> 0
A30: =IF(MONTH(C30)=MONTH(D$3),RIGHT('Yearly Info'!A$36,LEN('Yearly Info'!A$36)-4),"") -> #VALUE! | C30: =C29 -> 46055 | D30: =INDIRECT("'" & UPPER(LEFT(TEXT($D$3,"mmmm"),3)) & "'!B33") -> 0
A31: =IF(MONTH(C31)=MONTH(D$3),RIGHT('Yearly Info'!A$37,LEN('Yearly Info'!A$37)-4),"") -> #VALUE! | C31: =C30 -> 46055 | D31: =INDIRECT("'" & UPPER(LEFT(TEXT($D$3,"mmmm"),3)) & "'!B34") -> 0
A32: =IF(MONTH(C32)=MONTH(D$3),RIGHT('Yearly Info'!A$38,LEN('Yearly Info'!A$38)-4),"") -> #VALUE! | C32: =C31 -> 46055 | D32: =INDIRECT("'" & UPPER(LEFT(TEXT($D$3,"mmmm"),3)) & "'!B35") -> 0
A33: =IF(MONTH(C33)=MONTH(D$3),RIGHT('Yearly Info'!A$39,LEN('Yearly Info'!A$39)-4),"") -> #VALUE! | C33: =C32 -> 46055 | D33: =INDIRECT("'" & UPPER(LEFT(TEXT($D$3,"mmmm"),3)) & "'!B36") -> 0
